Workbook
Name nr_AllowedMonths: '[1]3_Master_Data'!$D$2:$D$4
Name nr_CostCenters: '[1]3_Master_Data'!$O$2:$O$6
Name nr_Countries: '[1]3_Master_Data'!$A$2:$A$6
Name nr_EntityTypes: '[1]3_Master_Data'!$F$2:$F$5
Name nr_PaymentTypes: '[1]3_Master_Data'!$I$2:$I$5
Name nr_ProjectCodes: '[1]3_Master_Data'!$Q$2:$Q$5

Sheet 05_Control_Dashboard
A1: AP CONTROL SUMMARY | D1: EOR CONTROL SUMMARY
A2: Total Transactions | B2: =COUNTA('02_Validation_Engine'!A:A)-1 -> 350 | D2: Total EOR Invoices | E2: =COUNTA('04_EOR_Reconciliation'!E:E)-1 -> 12
A3: Blocked Transactions | B3: =COUNTIF('02_Validation_Engine'!W:W,"Fail") -> 15 | D3: Total EOR Invoice Value | E3: =SUM('04_EOR_Reconciliation'!K:K) -> 1642753.6
A4: Ready For Approval | B4: =COUNTIF('02_Validation_Engine'!X:X,"Yes") -> 335 | D4: Unreconciled Invoices | E4: =COUNTIF('04_EOR_Reconciliation'!K:K,"Not Reconciled") -> 0
A5: Approval Rate % | B5: =IF(B2=0,0,B4/B2) -> 0.95714286 | D5: Control Status | E5: =IF(E4=0,"All EOR invoices reconciled","Attention Required") -> All EOR invoices reconciled
A6: Required Field Errors | B6: =COUNTIF('02_Validation_Engine'!P:P,"Fail") -> 5
A7: Amount Errors | B7: =COUNTIF('02_Validation_Engine'!Q:Q,"Fail") -> 5
A8: Bank Errors | B8: =COUNTIF('02_Validation_Engine'!U:U,"Fail") -> 2
A9: Duplicate Errors | B9: =COUNTIF('02_Validation_Engine'!V:V,"Fail") -> 2
A10: Currency Errors | B10: =COUNTIF('02_Validation_Engine'!R:R,"Fail") -> 1
A11: VAT Errors | B11: =COUNTIF('02_Validation_Engine'!T:T,"Fail") -> 1
A12: Exchange Rate Errors | B12: =COUNTIF('02_Validation_Engine'!S:S,"Fail") -> 0

Sheet 04_EOR_Reconciliation
A1: Month | B1: Country | C1: Currency | D1: EOR_Provider | E1: Invoice_Number | F1: Invoice_Date | G1: Employee_Count | H1: Expected_Payroll | I1: Employer_Tax_% | J1: Service_Fee_% | K1: Invoice_Total | L1: Paid_Amount | M1: Variance | N1: Status
A2: 46023 | B2: Jordan | C2: JOD | D2: =IF(B2="Jordan","Oyster", IF(B2="Germany","Oyster", IF(B2="USA","Remote", IF(B2="UAE","Deel","")))) -> Oyster | E2: =UPPER(LEFT(D2,3) & "-" & LEFT(B2,2) & "-" & TEXT(A2,"MMYY")) -> OYS-JO-0126 | F2: =EOMONTH(A2,0) -> 46053 | G2: =COUNTIFS( '02_Validation_Engine'!$G:$G,$A2, '02_Validation_Engine'!$D:$D,$B2, '02_Validation_Engine'!$C:$C,"Employee", '02_Validation_Engine'!$W:$W,"Pass", '02_Validation_Engine'!$X:$X,"Yes" ) -> 15 | H2: =SUMIFS( '02_Validation_Engine'!$M:$M, '02_Validation_Engine'!$G:$G,$A2, '02_Validation_Engine'!$D:$D,$B2, '02_Validation_Engine'!$C:$C,"Employee", '02_Validation_Engine'!$W:$W,"Pass", '02_Validation_Engine'!$X:$X,"Yes" ) -> 27437.82 | I2: 0.15 | J2: 0.05 | K2: =H2*(1+I2+J2) -> 32925.384 | L2: ='04_EOR_Reconciliation'!K2 -> 32925.384 | M2: =EOR[[#This Row],[Invoice_Total]]-EOR[[#This Row],[Paid_Amount]] -> 0 | N2: =IF(K2=L2,"Reconciled","Not Reconciled") -> Reconciled
A3: 46023 | B3: USA | C3: USD | D3: =IF(B3="Jordan","Oyster", IF(B3="Germany","Oyster", IF(B3="USA","Remote", IF(B3="UAE","Deel","")))) -> Remote | E3: =UPPER(LEFT(D3,3) & "-" & LEFT(B3,2) & "-" & TEXT(A3,"MMYY")) -> REM-US-0126 | F3: =EOMONTH(A3,0) -> 46053 | G3: =COUNTIFS( '02_Validation_Engine'!$G:$G,$A3, '02_Validation_Engine'!$D:$D,$B3, '02_Validation_Engine'!$C:$C,"Employee", '02_Validation_Engine'!$W:$W,"Pass", '02_Validation_Engine'!$X:$X,"Yes" ) -> 18 | H3: =SUMIFS( '02_Validation_Engine'!$M:$M, '02_Validation_Engine'!$G:$G,$A3, '02_Validation_Engine'!$D:$D,$B3, '02_Validation_Engine'!$C:$C,"Employee", '02_Validation_Engine'!$W:$W,"Pass", '02_Validation_Engine'!$X:$X,"Yes" ) -> 127990.64 | I3: 0.15 | J3: 0.05 | K3: =H3*(1+I3+J3) -> 153588.77 | L3: ='04_EOR_Reconciliation'!K3 -> 153588.77 | M3: =EOR[[#This Row],[Invoice_Total]]-EOR[[#This Row],[Paid_Amount]] -> 0 | N3: =IF(K3=L3,"Reconciled","Not Reconciled") -> Reconciled
A4: 46023 | B4: Germany | C4: EUR | D4: =IF(B4="Jordan","Oyster", IF(B4="Germany","Oyster", IF(B4="USA","Remote", IF(B4="UAE","Deel","")))) -> Oyster | E4: =UPPER(LEFT(D4,3) & "-" & LEFT(B4,2) & "-" & TEXT(A4,"MMYY")) -> OYS-GE-0126 | F4: =EOMONTH(A4,0) -> 46053 | G4: =COUNTIFS( '02_Validation_Engine'!$G:$G,$A4, '02_Validation_Engine'!$D:$D,$B4, '02_Validation_Engine'!$C:$C,"Employee", '02_Validation_Engine'!$W:$W,"Pass", '02_Validation_Engine'!$X:$X,"Yes" ) -> 12 | H4: =SUMIFS( '02_Validation_Engine'!$M:$M, '02_Validation_Engine'!$G:$G,$A4, '02_Validation_Engine'!$D:$D,$B4, '02_Validation_Engine'!$C:$C,"Employee", '02_Validation_Engine'!$W:$W,"Pass", '02_Validation_Engine'!$X:$X,"Yes" ) -> 72844.14 | I4: 0.15 | J4: 0.05 | K4: =H4*(1+I4+J4) -> 87412.968 | L4: ='04_EOR_Reconciliation'!K4 -> 87412.968 | M4: =EOR[[#This Row],[Invoice_Total]]-EOR[[#This Row],[Paid_Amount]] -> 0 | N4: =IF(K4=L4,"Reconciled","Not Reconciled") -> Reconciled
A5: 46023 | B5: UAE | C5: AED | D5: =IF(B5="Jordan","Oyster", IF(B5="Germany","Oyster", IF(B5="USA","Remote", IF(B5="UAE","Deel","")))) -> Deel | E5: =UPPER(LEFT(D5,3) & "-" & LEFT(B5,2) & "-" & TEXT(A5,"MMYY")) -> DEE-UA-0126 | F5: =EOMONTH(A5,0) -> 46053 | G5: =COUNTIFS( '02_Validation_Engine'!$G:$G,$A5, '02_Validation_Engine'!$D:$D,$B5, '02_Validation_Engine'!$C:$C,"Employee", '02_Validation_Engine'!$W:$W,"Pass", '02_Validation_Engine'!$X:$X,"Yes" ) -> 17 | H5: =SUMIFS( '02_Validation_Engine'!$M:$M, '02_Validation_Engine'!$G:$G,$A5, '02_Validation_Engine'!$D:$D,$B5, '02_Validation_Engine'!$C:$C,"Employee", '02_Validation_Engine'!$W:$W,"Pass", '02_Validation_Engine'!$X:$X,"Yes" ) -> 371120.55 | I5: 0.15 | J5: 0.05 | K5: =H5*(1+I5+J5) -> 445344.66 | L5: ='04_EOR_Reconciliation'!K5 -> 445344.66 | M5: =EOR[[#This Row],[Invoice_Total]]-EOR[[#This Row],[Paid_Amount]] -> 0 | N5: =IF(K5=L5,"Reconciled","Not Reconciled") -> Reconciled
A6: 46054 | B6: Jordan | C6: JOD | D6: =IF(B6="Jordan","Oyster", IF(B6="Germany","Oyster", IF(B6="USA","Remote", IF(B6="UAE","Deel","")))) -> Oyster | E6: =UPPER(LEFT(D6,3) & "-" & LEFT(B6,2) & "-" & TEXT(A6,"MMYY")) -> OYS-JO-0226 | F6: =EOMONTH(A6,0) -> 46081 | G6: =COUNTIFS( '02_Validation_Engine'!$G:$G,$A6, '02_Validation_Engine'!$D:$D,$B6, '02_Validation_Engine'!$C:$C,"Employee", '02_Validation_Engine'!$W:$W,"Pass", '02_Validation_Engine'!$X:$X,"Yes" ) -> 15 | H6: =SUMIFS( '02_Validation_Engine'!$M:$M, '02_Validation_Engine'!$G:$G,$A6, '02_Validation_Engine'!$D:$D,$B6, '02_Validation_Engine'!$C:$C,"Employee", '02_Validation_Engine'!$W:$W,"Pass", '02_Validation_Engine'!$X:$X,"Yes" ) -> 27442.47 | I6: 0.15 | J6: 0.05 | K6: =H6*(1+I6+J6) -> 32930.964 | L6: ='04_EOR_Reconciliation'!K6 -> 32930.964 | M6: =EOR[[#This Row],[Invoice_Total]]-EOR[[#This Row],[Paid_Amount]] -> 0 | N6: =IF(K6=L6,"Reconciled","Not Reconciled") -> Reconciled
A7: 46054 | B7: USA | C7: USD | D7: =IF(B7="Jordan","Oyster", IF(B7="Germany","Oyster", IF(B7="USA","Remote", IF(B7="UAE","Deel","")))) -> Remote | E7: =UPPER(LEFT(D7,3) & "-" & LEFT(B7,2) & "-" & TEXT(A7,"MMYY")) -> REM-US-0226 | F7: =EOMONTH(A7,0) -> 46081 | G7: =COUNTIFS( '02_Validation_Engine'!$G:$G,$A7, '02_Validation_Engine'!$D:$D,$B7, '02_Validation_Engine'!$C:$C,"Employee", '02_Validation_Engine'!$W:$W,"Pass", '02_Validation_Engine'!$X:$X,"Yes" ) -> 13 | H7: =SUMIFS( '02_Validation_Engine'!$M:$M, '02_Validation_Engine'!$G:$G,$A7, '02_Validation_Engine'!$D:$D,$B7, '02_Validation_Engine'!$C:$C,"Employee", '02_Validation_Engine'!$W:$W,"Pass", '02_Validation_Engine'!$X:$X,"Yes" ) -> 92854.43 | I7: 0.15 | J7: 0.05 | K7: =H7*(1+I7+J7) -> 111425.32 | L7: ='04_EOR_Reconciliation'!K7 -> 111425.32 | M7: =EOR[[#This Row],[Invoice_Total]]-EOR[[#This Row],[Paid_Amount]] -> 0 | N7: =IF(K7=L7,"Reconciled","Not Reconciled") -> Reconciled
A8: 46054 | B8: Germany | C8: EUR | D8: =IF(B8="Jordan","Oyster", IF(B8="Germany","Oyster", IF(B8="USA","Remote", IF(B8="UAE","Deel","")))) -> Oyster | E8: =UPPER(LEFT(D8,3) & "-" & LEFT(B8,2) & "-" & TEXT(A8,"MMYY")) -> OYS-GE-0226 | F8: =EOMONTH(A8,0) -> 46081 | G8: =COUNTIFS( '02_Validation_Engine'!$G:$G,$A8, '02_Validation_Engine'!$D:$D,$B8, '02_Validation_Engine'!$C:$C,"Employee", '02_Validation_Engine'!$W:$W,"Pass", '02_Validation_Engine'!$X:$X,"Yes" ) -> 13 | H8: =SUMIFS( '02_Validation_Engine'!$M:$M, '02_Validation_Engine'!$G:$G,$A8, '02_Validation_Engine'!$D:$D,$B8, '02_Validation_Engine'!$C:$C,"Employee", '02_Validation_Engine'!$W:$W,"Pass", '02_Validation_Engine'!$X:$X,"Yes" ) -> 78234.17 | I8: 0.15 | J8: 0.05 | K8: =H8*(1+I8+J8) -> 93881.004 | L8: ='04_EOR_Reconciliation'!K8 -> 93881.004 | M8: =EOR[[#This Row],[Invoice_Total]]-EOR[[#This Row],[Paid_Amount]] -> 0 | N8: =IF(K8=L8,"Reconciled","Not Reconciled") -> Reconciled
A9: 46054 | B9: UAE | C9: AED | D9: =IF(B9="Jordan","Oyster", IF(B9="Germany","Oyster", IF(B9="USA","Remote", IF(B9="UAE","Deel","")))) -> Deel | E9: =UPPER(LEFT(D9,3) & "-" & LEFT(B9,2) & "-" & TEXT(A9,"MMYY")) -> DEE-UA-0226 | F9: =EOMONTH(A9,0) -> 46081 | G9: =COUNTIFS( '02_Validation_Engine'!$G:$G,$A9, '02_Validation_Engine'!$D:$D,$B9, '02_Validation_Engine'!$C:$C,"Employee", '02_Validation_Engine'!$W:$W,"Pass", '02_Validation_Engine'!$X:$X,"Yes" ) -> 10 | H9: =SUMIFS( '02_Validation_Engine'!$M:$M, '02_Validation_Engine'!$G:$G,$A9, '02_Validation_Engine'!$D:$D,$B9, '02_Validation_Engine'!$C:$C,"Employee", '02_Validation_Engine'!$W:$W,"Pass", '02_Validation_Engine'!$X:$X,"Yes" ) -> 226770.84 | I9: 0.15 | J9: 0.05 | K9: =H9*(1+I9+J9) -> 272125.01 | L9: ='04_EOR_Reconciliation'!K9 -> 272125.01 | M9: =EOR[[#This Row],[Invoice_Total]]-EOR[[#This Row],[Paid_Amount]] -> 0 | N9: =IF(K9=L9,"Reconciled","Not Reconciled") -> Reconciled
A10: 46082 | B10: Jordan | C10: JOD | D10: =IF(B10="Jordan","Oyster", IF(B10="Germany","Oyster", IF(B10="USA","Remote", IF(B10="UAE","Deel","")))) -> Oyster | E10: =UPPER(LEFT(D10,3) & "-" & LEFT(B10,2) & "-" & TEXT(A10,"MMYY")) -> OYS-JO-0326 | F10: =EOMONTH(A10,0) -> 46112 | G10: =COUNTIFS( '02_Validation_Engine'!$G:$G,$A10, '02_Validation_Engine'!$D:$D,$B10, '02_Validation_Engine'!$C:$C,"Employee", '02_Validation_Engine'!$W:$W,"Pass", '02_Validation_Engine'!$X:$X,"Yes" ) -> 10 | H10: =SUMIFS( '02_Validation_Engine'!$M:$M, '02_Validation_Engine'!$G:$G,$A10, '02_Validation_Engine'!$D:$D,$B10, '02_Validation_Engine'!$C:$C,"Employee", '02_Validation_Engine'!$W:$W,"Pass", '02_Validation_Engine'!$X:$X,"Yes" ) -> 18005.8 | I10: 0.15 | J10: 0.05 | K10: =H10*(1+I10+J10) -> 21606.96 | L10: ='04_EOR_Reconciliation'!K10 -> 21606.96 | M10: =EOR[[#This Row],[Invoice_Total]]-EOR[[#This Row],[Paid_Amount]] -> 0 | N10: =IF(K10=L10,"Reconciled","Not Reconciled") -> Reconciled
A11: 46082 | B11: USA | C11: USD | D11: =IF(B11="Jordan","Oyster", IF(B11="Germany","Oyster", IF(B11="USA","Remote", IF(B11="UAE","Deel","")))) -> Remote | E11: =UPPER(LEFT(D11,3) & "-" & LEFT(B11,2) & "-" & TEXT(A11,"MMYY")) -> REM-US-0326 | F11: =EOMONTH(A11,0) -> 46112 | G11: =COUNTIFS( '02_Validation_Engine'!$G:$G,$A11, '02_Validation_Engine'!$D:$D,$B11, '02_Validation_Engine'!$C:$C,"Employee", '02_Validation_Engine'!$W:$W,"Pass", '02_Validation_Engine'!$X:$X,"Yes" ) -> 12 | H11: =SUMIFS( '02_Validation_Engine'!$M:$M, '02_Validation_Engine'!$G:$G,$A11, '02_Validation_Engine'!$D:$D,$B11, '02_Validation_Engine'!$C:$C,"Employee", '02_Validation_Engine'!$W:$W,"Pass", '02_Validation_Engine'!$X:$X,"Yes" ) -> 86738.08 | I11: 0.15 | J11: 0.05 | K11: =H11*(1+I11+J11) -> 104085.7 | L11: ='04_EOR_Reconciliation'!K11 -> 104085.7 | M11: =EOR[[#This Row],[Invoice_Total]]-EOR[[#This Row],[Paid_Amount]] -> 0 | N11: =IF(K11=L11,"Reconciled","Not Reconciled") -> Reconciled
A12: 46082 | B12: Germany | C12: EUR | D12: =IF(B12="Jordan","Oyster", IF(B12="Germany","Oyster", IF(B12="USA","Remote", IF(B12="UAE","Deel","")))) -> Oyster | E12: =UPPER(LEFT(D12,3) & "-" & LEFT(B12,2) & "-" & TEXT(A12,"MMYY")) -> OYS-GE-0326 | F12: =EOMONTH(A12,0) -> 46112 | G12: =COUNTIFS( '02_Validation_Engine'!$G:$G,$A12, '02_Validation_Engine'!$D:$D,$B12, '02_Validation_Engine'!$C:$C,"Employee", '02_Validation_Engine'!$W:$W,"Pass", '02_Validation_Engine'!$X:$X,"Yes" ) -> 10 | H12: =SUMIFS( '02_Validation_Engine'!$M:$M, '02_Validation_Engine'!$G:$G,$A12, '02_Validation_Engine'!$D:$D,$B12, '02_Validation_Engine'!$C:$C,"Employee", '02_Validation_Engine'!$W:$W,"Pass", '02_Validation_Engine'!$X:$X,"Yes" ) -> 61273.14 | I12: 0.15 | J12: 0.05 | K12: =H12*(1+I12+J12) -> 73527.768 | L12: ='04_EOR_Reconciliation'!K12 -> 73527.768 | M12: =EOR[[#This Row],[Invoice_Total]]-EOR[[#This Row],[Paid_Amount]] -> 0 | N12: =IF(K12=L12,"Reconciled","Not Reconciled") -> Reconciled
A13: 46082 | B13: UAE | C13: AED | D13: =IF(B13="Jordan","Oyster", IF(B13="Germany","Oyster", IF(B13="USA","Remote", IF(B13="UAE","Deel","")))) -> Deel | E13: =UPPER(LEFT(D13,3) & "-" & LEFT(B13,2) & "-" & TEXT(A13,"MMYY")) -> DEE-UA-0326 | F13: =EOMONTH(A13,0) -> 46112 | G13: =COUNTIFS( '02_Validation_Engine'!$G:$G,$A13, '02_Validation_Engine'!$D:$D,$B13, '02_Validation_Engine'!$C:$C,"Employee", '02_Validation_Engine'!$W:$W,"Pass", '02_Validation_Engine'!$X:$X,"Yes" ) -> 8 | H13: =SUMIFS( '02_Validation_Engine'!$M:$M, '02_Validation_Engine'!$G:$G,$A13, '02_Validation_Engine'!$D:$D,$B13, '02_Validation_Engine'!$C:$C,"Employee", '02_Validation_Engine'!$W:$W,"Pass", '02_Validation_Engine'!$X:$X,"Yes" ) -> 178249.22 | I13: 0.15 | J13: 0.05 | K13: =H13*(1+I13+J13) -> 213899.06 | L13: ='04_EOR_Reconciliation'!K13 -> 213899.06 | M13: =EOR[[#This Row],[Invoice_Total]]-EOR[[#This Row],[Paid_Amount]] -> 0 | N13: =IF(K13=L13,"Reconciled","Not Reconciled") -> Reconciled

Sheet 03_Payment_Batch
A1: Record_ID | B1: Month | C1: Payment_Type | D1: Name | E1: Country | F1: Currency | G1: Gross_Amount | H1: Exchange_Rate | I1: Amount_CHF | J1: Bank_Account
A2: 1 | B2: =IFERROR(VLOOKUP($A2,'02_Validation_Engine'!$A:$X,7,FALSE),"") -> Feb-2026 | C2: Payroll | D2: Omar Müller | E2: Jordan | F2: JOD | G2: 1687.14 | H2: 1.08643 | I2: 1832.96 | J2: JO-IBAN-00024690
A3: 3 | B3: =IFERROR(VLOOKUP($A3,'02_Validation_Engine'!$A:$X,7,FALSE),"") -> Feb-2026 | C3: Payroll | D3: David Wilson | E3: USA | F3: USD | G3: 7521.5 | H3: 0.77018 | I3: 5792.91 | J3: US-RT-000004936-AC-0000022712
A4: 4 | B4: =IFERROR(VLOOKUP($A4,'02_Validation_Engine'!$A:$X,7,FALSE),"") -> Mar-2026 | C4: Payroll | D4: John Smith | E4: USA | F4: USD | G4: 7077 | H4: 0.77018 | I4: 5450.56 | J4: US-RT-000006170-AC-0000028390
A5: 5 | B5: =IFERROR(VLOOKUP($A5,'02_Validation_Engine'!$A:$X,7,FALSE),"") -> Feb-2026 | C5: Payroll | D5: Anna Khan | E5: Germany | F5: EUR | G5: 5455.2 | H5: 0.90888 | I5: 4958.12 | J5: DE890000000000081474
A6: 6 | B6: =IFERROR(VLOOKUP($A6,'02_Validation_Engine'!$A:$X,7,FALSE),"") -> Jan-2026 | C6: Payroll | D6: David Haddad | E6: Germany | F6: EUR | G6: 5775 | H6: 0.90888 | I6: 5248.78 | J6: DE890000000000095053
A7: 7 | B7: =IFERROR(VLOOKUP($A7,'02_Validation_Engine'!$A:$X,7,FALSE),"") -> Mar-2026 | C7: Payroll | D7: Anna Taylor | E7: Jordan | F7: JOD | G7: 1837.8 | H7: 1.08643 | I7: 1996.64 | J7: JO-IBAN-00098760
A8: 8 | B8: =IFERROR(VLOOKUP($A8,'02_Validation_Engine'!$A:$X,7,FALSE),"") -> Mar-2026 | C8: Payroll | D8: David Khan | E8: Germany | F8: EUR | G8: 6138.6 | H8: 0.90888 | I8: 5579.25 | J8: DE890000000000122211
A9: 9 | B9: =IFERROR(VLOOKUP($A9,'02_Validation_Engine'!$A:$X,7,FALSE),"") -> Mar-2026 | C9: Payroll | D9: Lina Wilson | E9: USA | F9: USD | G9: 7459.9 | H9: 0.77018 | I9: 5745.47 | J9: US-RT-000012340-AC-0000056780
A10: 10 | B10: =IFERROR(VLOOKUP($A10,'02_Validation_Engine'!$A:$X,7,FALSE),"") -> Mar-2026 | C10: Payroll | D10: Michael Wilson | E10: USA | F10: USD | G10: 7142.8 | H10: 0.77018 | I10: 5501.24 | J10: US-RT-000013574-AC-0000062458
A11: 11 | B11: =IFERROR(VLOOKUP($A11,'02_Validation_Engine'!$A:$X,7,FALSE),"") -> Feb-2026 | C11: Payroll | D11: David Smith | E11: Jordan | F11: JOD | G11: 1971.72 | H11: 1.08643 | I11: 2142.14 | J11: JO-IBAN-00148140
A12: 12 | B12: =IFERROR(VLOOKUP($A12,'02_Validation_Engine'!$A:$X,7,FALSE),"") -> Jan-2026 | C12: Payroll | D12: Michael Wilson | E12: USA | F12: USD | G12: 7249.94 | H12: 0.77018 | I12: 5583.76 | J12: US-RT-000013574-AC-0000062458
A13: 13 | B13: =IFERROR(VLOOKUP($A13,'02_Validation_Engine'!$A:$X,7,FALSE),"") -> Jan-2026 | C13: Payroll | D13: Julia Smith | E13: Switzerland | F13: CHF | G13: 6364.8 | H13: 1 | I13: 6364.8 | J13: CH930000000000320840
... A331: 349 | B331: =IFERROR(VLOOKUP($A331,'02_Validation_Engine'!$A:$X,7,FALSE),"") -> Mar-2026 | C331: Grant_Disbursement | D331: Regional Advocacy Network | E331: Switzerland | F331: CHF | G331: 51885.6 | H331: 1 | I331: 51885.6 | J331: JO-IBAN-01296225

Sheet 02_Validation_Engine
A1: Record_ID | B1: Payment_Type | C1: Entity_Type | D1: Country | E1: Name | F1: Bank_Account | G1: Month | H1: Currency | I1: Net_Amount | J1: VAT_Applicable | K1: VAT_Rate | L1: VAT_Amount | M1: Gross_Amount | N1: Exchange_Rate | O1: Amount_CHF | P1: RequiredField_Validation | Q1: Amount_Validation | R1: Currency_Validation | S1: ExchangeRate_Validation | T1: VAT_Validation | U1: Bank_Validation | V1: Duplicate_Validation | W1: Validation_Result | X1: Ready_For_Approval
A2: =RawTable[[#This Row],[Record_ID]] -> 1 | B2: =RawTable[[#This Row],[Payment_Type]] -> Payroll | C2: =RawTable[[#This Row],[Entity_Type]] -> Employee | D2: =RawTable[[#This Row],[Country]] -> Jordan | E2: =RawTable[[#This Row],[Name]] -> Omar Müller | F2: =RawTable[[#This Row],[Bank_Account]] -> JO-IBAN-00024690 | G2: =RawTable[[#This Row],[Month]] -> Feb-2026 | H2: =RawTable[[#This Row],[Currency]] -> JOD | I2: =RawTable[[#This Row],[Net_Amount]] -> 1687.14 | J2: =RawTable[[#This Row],[VAT_Applicable]] -> No | K2: =RawTable[[#This Row],[VAT_Rate]] -> 0 | L2: =RawTable[[#This Row],[VAT_Amount]] -> 0 | M2: =RawTable[[#This Row],[Gross_Amount]] -> 1687.14 | N2: =RawTable[[#This Row],[Exchange_Rate]] -> 1.08643 | O2: =RawTable[[#This Row],[Amount_CHF]] -> 1832.96 | P2: =IF( OR(ValidationTable[[#This Row],[Record_ID]]="",ValidationTable[[#This Row],[Payment_Type]]="",ValidationTable[[#This Row],[Entity_Type]]="", ValidationTable[[#This Row],[Country]]="", ValidationTable[[#This Row],[Name]]="", ValidationTable[[#This Row],[Month]]="", ValidationTable[[#This Row],[Currency]]="" ), "Fail", "Pass" ) -> Pass | Q2: =IF( OR(ValidationTable[[#This Row],[Net_Amount]]<=0, ROUND(ValidationTable[[#This Row],[Net_Amount]]+ValidationTable[[#This Row],[VAT_Amount]],2)<>ROUND(ValidationTable[[#This Row],[Gross_Amount]],2) ), "Fail", "Pass" ) -> Pass | R2: =IF(ValidationTable[[#This Row],[Currency]]="","Fail","Pass") -> Pass | S2: =IF( ValidationTable[[#This Row],[Currency]]="CHF", IF(ValidationTable[[#This Row],[Exchange_Rate]]<>1,"Fail","Pass"), IF(ValidationTable[[#This Row],[Exchange_Rate]]<=0,"Fail","Pass") ) -> Pass | T2: =IF(ValidationTable[[#This Row],[VAT_Applicable]]="Yes", IF( ROUND(ValidationTable[[#This Row],[Net_Amount]]*ValidationTable[[#This Row],[VAT_Rate]],2)<>ROUND(ValidationTable[[#This Row],[VAT_Amount]],2), "Fail", "Pass" ), IF( OR(ValidationTable[[#This Row],[VAT_Rate]]<>0,ValidationTable[[#This Row],[VAT_Amount]]<>0 ), "Fail", "Pass" ) ) -> Pass | U2: =IF(LEN(TRIM(ValidationTable[[#This Row],[Bank_Account]]))=0,"Fail","Pass") -> Pass | V2: =IF( COUNTIF(ValidationTable[Record_ID],ValidationTable[[#This Row],[Record_ID]])>1, "Fail", "Pass" ) -> Pass | W2: =IF( COUNTIF(ValidationTable[[#This Row],[RequiredField_Validation]]:ValidationTable[[#This Row],[Duplicate_Validation]],"Fail")>0, "Fail", "Pass" ) -> Pass | X2: =IF(ValidationTable[[#This Row],[Validation_Result]]="Pass","Yes","No") -> Yes
A3: =RawTable[[#This Row],[Record_ID]] -> 2 | B3: =RawTable[[#This Row],[Payment_Type]] -> Payroll | C3: =RawTable[[#This Row],[Entity_Type]] -> Employee | D3: =RawTable[[#This Row],[Country]] -> USA | E3: =RawTable[[#This Row],[Name]] -> Ahmed Schmidt | F3: =RawTable[[#This Row],[Bank_Account]] -> US-RT-000003702-AC-0000017034 | G3: =RawTable[[#This Row],[Month]] -> Mar-2026 | H3: =RawTable[[#This Row],[Currency]] -> USD | I3: =RawTable[[#This Row],[Net_Amount]] -> 0 | J3: =RawTable[[#This Row],[VAT_Applicable]] -> No | K3: =RawTable[[#This Row],[VAT_Rate]] -> 0 | L3: =RawTable[[#This Row],[VAT_Amount]] -> 0 | M3: =RawTable[[#This Row],[Gross_Amount]] -> 0 | N3: =RawTable[[#This Row],[Exchange_Rate]] -> 0.77018 | O3: =RawTable[[#This Row],[Amount_CHF]] -> 0 | P3: =IF( OR(ValidationTable[[#This Row],[Record_ID]]="",ValidationTable[[#This Row],[Payment_Type]]="",ValidationTable[[#This Row],[Entity_Type]]="", ValidationTable[[#This Row],[Country]]="", ValidationTable[[#This Row],[Name]]="", ValidationTable[[#This Row],[Month]]="", ValidationTable[[#This Row],[Currency]]="" ), "Fail", "Pass" ) -> Pass | Q3: =IF( OR(ValidationTable[[#This Row],[Net_Amount]]<=0, ROUND(ValidationTable[[#This Row],[Net_Amount]]+ValidationTable[[#This Row],[VAT_Amount]],2)<>ROUND(ValidationTable[[#This Row],[Gross_Amount]],2) ), "Fail", "Pass" ) -> Fail | R3: =IF(ValidationTable[[#This Row],[Currency]]="","Fail","Pass") -> Pass | S3: =IF( ValidationTable[[#This Row],[Currency]]="CHF", IF(ValidationTable[[#This Row],[Exchange_Rate]]<>1,"Fail","Pass"), IF(ValidationTable[[#This Row],[Exchange_Rate]]<=0,"Fail","Pass") ) -> Pass | T3: =IF(ValidationTable[[#This Row],[VAT_Applicable]]="Yes", IF( ROUND(ValidationTable[[#This Row],[Net_Amount]]*ValidationTable[[#This Row],[VAT_Rate]],2)<>ROUND(ValidationTable[[#This Row],[VAT_Amount]],2), "Fail", "Pass" ), IF( OR(ValidationTable[[#This Row],[VAT_Rate]]<>0,ValidationTable[[#This Row],[VAT_Amount]]<>0 ), "Fail", "Pass" ) ) -> Pass | U3: =IF(LEN(TRIM(ValidationTable[[#This Row],[Bank_Account]]))=0,"Fail","Pass") -> Pass | V3: =IF( COUNTIF(ValidationTable[Record_ID],ValidationTable[[#This Row],[Record_ID]])>1, "Fail", "Pass" ) -> Pass | W3: =IF( COUNTIF(ValidationTable[[#This Row],[RequiredField_Validation]]:ValidationTable[[#This Row],[Duplicate_Validation]],"Fail")>0, "Fail", "Pass" ) -> Fail | X3: =IF(ValidationTable[[#This Row],[Validation_Result]]="Pass","Yes","No") -> No
A4: =RawTable[[#This Row],[Record_ID]] -> 3 | B4: =RawTable[[#This Row],[Payment_Type]] -> Payroll | C4: =RawTable[[#This Row],[Entity_Type]] -> Employee | D4: =RawTable[[#This Row],[Country]] -> USA | E4: =RawTable[[#This Row],[Name]] -> David Wilson | F4: =RawTable[[#This Row],[Bank_Account]] -> US-RT-000004936-AC-0000022712 | G4: =RawTable[[#This Row],[Month]] -> Feb-2026 | H4: =RawTable[[#This Row],[Currency]] -> USD | I4: =RawTable[[#This Row],[Net_Amount]] -> 7521.5 | J4: =RawTable[[#This Row],[VAT_Applicable]] -> No | K4: =RawTable[[#This Row],[VAT_Rate]] -> 0 | L4: =RawTable[[#This Row],[VAT_Amount]] -> 0 | M4: =RawTable[[#This Row],[Gross_Amount]] -> 7521.5 | N4: =RawTable[[#This Row],[Exchange_Rate]] -> 0.77018 | O4: =RawTable[[#This Row],[Amount_CHF]] -> 5792.91 | P4: =IF( OR(ValidationTable[[#This Row],[Record_ID]]="",ValidationTable[[#This Row],[Payment_Type]]="",ValidationTable[[#This Row],[Entity_Type]]="", ValidationTable[[#This Row],[Country]]="", ValidationTable[[#This Row],[Name]]="", ValidationTable[[#This Row],[Month]]="", ValidationTable[[#This Row],[Currency]]="" ), "Fail", "Pass" ) -> Pass | Q4: =IF( OR(ValidationTable[[#This Row],[Net_Amount]]<=0, ROUND(ValidationTable[[#This Row],[Net_Amount]]+ValidationTable[[#This Row],[VAT_Amount]],2)<>ROUND(ValidationTable[[#This Row],[Gross_Amount]],2) ), "Fail", "Pass" ) -> Pass | R4: =IF(ValidationTable[[#This Row],[Currency]]="","Fail","Pass") -> Pass | S4: =IF( ValidationTable[[#This Row],[Currency]]="CHF", IF(ValidationTable[[#This Row],[Exchange_Rate]]<>1,"Fail","Pass"), IF(ValidationTable[[#This Row],[Exchange_Rate]]<=0,"Fail","Pass") ) -> Pass | T4: =IF(ValidationTable[[#This Row],[VAT_Applicable]]="Yes", IF( ROUND(ValidationTable[[#This Row],[Net_Amount]]*ValidationTable[[#This Row],[VAT_Rate]],2)<>ROUND(ValidationTable[[#This Row],[VAT_Amount]],2), "Fail", "Pass" ), IF( OR(ValidationTable[[#This Row],[VAT_Rate]]<>0,ValidationTable[[#This Row],[VAT_Amount]]<>0 ), "Fail", "Pass" ) ) -> Pass | U4: =IF(LEN(TRIM(ValidationTable[[#This Row],[Bank_Account]]))=0,"Fail","Pass") -> Pass | V4: =IF( COUNTIF(ValidationTable[Record_ID],ValidationTable[[#This Row],[Record_ID]])>1, "Fail", "Pass" ) -> Pass | W4: =IF( COUNTIF(ValidationTable[[#This Row],[RequiredField_Validation]]:ValidationTable[[#This Row],[Duplicate_Validation]],"Fail")>0, "Fail", "Pass" ) -> Pass | X4: =IF(ValidationTable[[#This Row],[Validation_Result]]="Pass","Yes","No") -> Yes
A5: =RawTable[[#This Row],[Record_ID]] -> 4 | B5: =RawTable[[#This Row],[Payment_Type]] -> Payroll | C5: =RawTable[[#This Row],[Entity_Type]] -> Employee | D5: =RawTable[[#This Row],[Country]] -> USA | E5: =RawTable[[#This Row],[Name]] -> John Smith | F5: =RawTable[[#This Row],[Bank_Account]] -> US-RT-000006170-AC-0000028390 | G5: =RawTable[[#This Row],[Month]] -> Mar-2026 | H5: =RawTable[[#This Row],[Currency]] -> USD | I5: =RawTable[[#This Row],[Net_Amount]] -> 7077 | J5: =RawTable[[#This Row],[VAT_Applicable]] -> No | K5: =RawTable[[#This Row],[VAT_Rate]] -> 0 | L5: =RawTable[[#This Row],[VAT_Amount]] -> 0 | M5: =RawTable[[#This Row],[Gross_Amount]] -> 7077 | N5: =RawTable[[#This Row],[Exchange_Rate]] -> 0.77018 | O5: =RawTable[[#This Row],[Amount_CHF]] -> 5450.56 | P5: =IF( OR(ValidationTable[[#This Row],[Record_ID]]="",ValidationTable[[#This Row],[Payment_Type]]="",ValidationTable[[#This Row],[Entity_Type]]="", ValidationTable[[#This Row],[Country]]="", ValidationTable[[#This Row],[Name]]="", ValidationTable[[#This Row],[Month]]="", ValidationTable[[#This Row],[Currency]]="" ), "Fail", "Pass" ) -> Pass | Q5: =IF( OR(ValidationTable[[#This Row],[Net_Amount]]<=0, ROUND(ValidationTable[[#This Row],[Net_Amount]]+ValidationTable[[#This Row],[VAT_Amount]],2)<>ROUND(ValidationTable[[#This Row],[Gross_Amount]],2) ), "Fail", "Pass" ) -> Pass | R5: =IF(ValidationTable[[#This Row],[Currency]]="","Fail","Pass") -> Pass | S5: =IF( ValidationTable[[#This Row],[Currency]]="CHF", IF(ValidationTable[[#This Row],[Exchange_Rate]]<>1,"Fail","Pass"), IF(ValidationTable[[#This Row],[Exchange_Rate]]<=0,"Fail","Pass") ) -> Pass | T5: =IF(ValidationTable[[#This Row],[VAT_Applicable]]="Yes", IF( ROUND(ValidationTable[[#This Row],[Net_Amount]]*ValidationTable[[#This Row],[VAT_Rate]],2)<>ROUND(ValidationTable[[#This Row],[VAT_Amount]],2), "Fail", "Pass" ), IF( OR(ValidationTable[[#This Row],[VAT_Rate]]<>0,ValidationTable[[#This Row],[VAT_Amount]]<>0 ), "Fail", "Pass" ) ) -> Pass | U5: =IF(LEN(TRIM(ValidationTable[[#This Row],[Bank_Account]]))=0,"Fail","Pass") -> Pass | V5: =IF( COUNTIF(ValidationTable[Record_ID],ValidationTable[[#This Row],[Record_ID]])>1, "Fail", "Pass" ) -> Pass | W5: =IF( COUNTIF(ValidationTable[[#This Row],[RequiredField_Validation]]:ValidationTable[[#This Row],[Duplicate_Validation]],"Fail")>0, "Fail", "Pass" ) -> Pass | X5: =IF(ValidationTable[[#This Row],[Validation_Result]]="Pass","Yes","No") -> Yes
A6: =RawTable[[#This Row],[Record_ID]] -> 5 | B6: =RawTable[[#This Row],[Payment_Type]] -> Payroll | C6: =RawTable[[#This Row],[Entity_Type]] -> Employee | D6: =RawTable[[#This Row],[Country]] -> Germany | E6: =RawTable[[#This Row],[Name]] -> Anna Khan | F6: =RawTable[[#This Row],[Bank_Account]] -> DE890000000000081474 | G6: =RawTable[[#This Row],[Month]] -> Feb-2026 | H6: =RawTable[[#This Row],[Currency]] -> EUR | I6: =RawTable[[#This Row],[Net_Amount]] -> 5455.2 | J6: =RawTable[[#This Row],[VAT_Applicable]] -> No | K6: =RawTable[[#This Row],[VAT_Rate]] -> 0 | L6: =RawTable[[#This Row],[VAT_Amount]] -> 0 | M6: =RawTable[[#This Row],[Gross_Amount]] -> 5455.2 | N6: =RawTable[[#This Row],[Exchange_Rate]] -> 0.90888 | O6: =RawTable[[#This Row],[Amount_CHF]] -> 4958.12 | P6: =IF( OR(ValidationTable[[#This Row],[Record_ID]]="",ValidationTable[[#This Row],[Payment_Type]]="",ValidationTable[[#This Row],[Entity_Type]]="", ValidationTable[[#This Row],[Country]]="", ValidationTable[[#This Row],[Name]]="", ValidationTable[[#This Row],[Month]]="", ValidationTable[[#This Row],[Currency]]="" ), "Fail", "Pass" ) -> Pass | Q6: =IF( OR(ValidationTable[[#This Row],[Net_Amount]]<=0, ROUND(ValidationTable[[#This Row],[Net_Amount]]+ValidationTable[[#This Row],[VAT_Amount]],2)<>ROUND(ValidationTable[[#This Row],[Gross_Amount]],2) ), "Fail", "Pass" ) -> Pass | R6: =IF(ValidationTable[[#This Row],[Currency]]="","Fail","Pass") -> Pass | S6: =IF( ValidationTable[[#This Row],[Currency]]="CHF", IF(ValidationTable[[#This Row],[Exchange_Rate]]<>1,"Fail","Pass"), IF(ValidationTable[[#This Row],[Exchange_Rate]]<=0,"Fail","Pass") ) -> Pass | T6: =IF(ValidationTable[[#This Row],[VAT_Applicable]]="Yes", IF( ROUND(ValidationTable[[#This Row],[Net_Amount]]*ValidationTable[[#This Row],[VAT_Rate]],2)<>ROUND(ValidationTable[[#This Row],[VAT_Amount]],2), "Fail", "Pass" ), IF( OR(ValidationTable[[#This Row],[VAT_Rate]]<>0,ValidationTable[[#This Row],[VAT_Amount]]<>0 ), "Fail", "Pass" ) ) -> Pass | U6: =IF(LEN(TRIM(ValidationTable[[#This Row],[Bank_Account]]))=0,"Fail","Pass") -> Pass | V6: =IF( COUNTIF(ValidationTable[Record_ID],ValidationTable[[#This Row],[Record_ID]])>1, "Fail", "Pass" ) -> Pass | W6: =IF( COUNTIF(ValidationTable[[#This Row],[RequiredField_Validation]]:ValidationTable[[#This Row],[Duplicate_Validation]],"Fail")>0, "Fail", "Pass" ) -> Pass | X6: =IF(ValidationTable[[#This Row],[Validation_Result]]="Pass","Yes","No") -> Yes
A7: =RawTable[[#This Row],[Record_ID]] -> 6 | B7: =RawTable[[#This Row],[Payment_Type]] -> Payroll | C7: =RawTable[[#This Row],[Entity_Type]] -> Employee | D7: =RawTable[[#This Row],[Country]] -> Germany | E7: =RawTable[[#This Row],[Name]] -> David Haddad | F7: =RawTable[[#This Row],[Bank_Account]] -> DE890000000000095053 | G7: =RawTable[[#This Row],[Month]] -> Jan-2026 | H7: =RawTable[[#This Row],[Currency]] -> EUR | I7: =RawTable[[#This Row],[Net_Amount]] -> 5775 | J7: =RawTable[[#This Row],[VAT_Applicable]] -> No | K7: =RawTable[[#This Row],[VAT_Rate]] -> 0 | L7: =RawTable[[#This Row],[VAT_Amount]] -> 0 | M7: =RawTable[[#This Row],[Gross_Amount]] -> 5775 | N7: =RawTable[[#This Row],[Exchange_Rate]] -> 0.90888 | O7: =RawTable[[#This Row],[Amount_CHF]] -> 5248.78 | P7: =IF( OR(ValidationTable[[#This Row],[Record_ID]]="",ValidationTable[[#This Row],[Payment_Type]]="",ValidationTable[[#This Row],[Entity_Type]]="", ValidationTable[[#This Row],[Country]]="", ValidationTable[[#This Row],[Name]]="", ValidationTable[[#This Row],[Month]]="", ValidationTable[[#This Row],[Currency]]="" ), "Fail", "Pass" ) -> Pass | Q7: =IF( OR(ValidationTable[[#This Row],[Net_Amount]]<=0, ROUND(ValidationTable[[#This Row],[Net_Amount]]+ValidationTable[[#This Row],[VAT_Amount]],2)<>ROUND(ValidationTable[[#This Row],[Gross_Amount]],2) ), "Fail", "Pass" ) -> Pass | R7: =IF(ValidationTable[[#This Row],[Currency]]="","Fail","Pass") -> Pass | S7: =IF( ValidationTable[[#This Row],[Currency]]="CHF", IF(ValidationTable[[#This Row],[Exchange_Rate]]<>1,"Fail","Pass"), IF(ValidationTable[[#This Row],[Exchange_Rate]]<=0,"Fail","Pass") ) -> Pass | T7: =IF(ValidationTable[[#This Row],[VAT_Applicable]]="Yes", IF( ROUND(ValidationTable[[#This Row],[Net_Amount]]*ValidationTable[[#This Row],[VAT_Rate]],2)<>ROUND(ValidationTable[[#This Row],[VAT_Amount]],2), "Fail", "Pass" ), IF( OR(ValidationTable[[#This Row],[VAT_Rate]]<>0,ValidationTable[[#This Row],[VAT_Amount]]<>0 ), "Fail", "Pass" ) ) -> Pass | U7: =IF(LEN(TRIM(ValidationTable[[#This Row],[Bank_Account]]))=0,"Fail","Pass") -> Pass | V7: =IF( COUNTIF(ValidationTable[Record_ID],ValidationTable[[#This Row],[Record_ID]])>1, "Fail", "Pass" ) -> Pass | W7: =IF( COUNTIF(ValidationTable[[#This Row],[RequiredField_Validation]]:ValidationTable[[#This Row],[Duplicate_Validation]],"Fail")>0, "Fail", "Pass" ) -> Pass | X7: =IF(ValidationTable[[#This Row],[Validation_Result]]="Pass","Yes","No") -> Yes
A8: =RawTable[[#This Row],[Record_ID]] -> 7 | B8: =RawTable[[#This Row],[Payment_Type]] -> Payroll | C8: =RawTable[[#This Row],[Entity_Type]] -> Employee | D8: =RawTable[[#This Row],[Country]] -> Jordan | E8: =RawTable[[#This Row],[Name]] -> Anna Taylor | F8: =RawTable[[#This Row],[Bank_Account]] -> JO-IBAN-00098760 | G8: =RawTable[[#This Row],[Month]] -> Mar-2026 | H8: =RawTable[[#This Row],[Currency]] -> JOD | I8: =RawTable[[#This Row],[Net_Amount]] -> 1837.8 | J8: =RawTable[[#This Row],[VAT_Applicable]] -> No | K8: =RawTable[[#This Row],[VAT_Rate]] -> 0 | L8: =RawTable[[#This Row],[VAT_Amount]] -> 0 | M8: =RawTable[[#This Row],[Gross_Amount]] -> 1837.8 | N8: =RawTable[[#This Row],[Exchange_Rate]] -> 1.08643 | O8: =RawTable[[#This Row],[Amount_CHF]] -> 1996.64 | P8: =IF( OR(ValidationTable[[#This Row],[Record_ID]]="",ValidationTable[[#This Row],[Payment_Type]]="",ValidationTable[[#This Row],[Entity_Type]]="", ValidationTable[[#This Row],[Country]]="", ValidationTable[[#This Row],[Name]]="", ValidationTable[[#This Row],[Month]]="", ValidationTable[[#This Row],[Currency]]="" ), "Fail", "Pass" ) -> Pass | Q8: =IF( OR(ValidationTable[[#This Row],[Net_Amount]]<=0, ROUND(ValidationTable[[#This Row],[Net_Amount]]+ValidationTable[[#This Row],[VAT_Amount]],2)<>ROUND(ValidationTable[[#This Row],[Gross_Amount]],2) ), "Fail", "Pass" ) -> Pass | R8: =IF(ValidationTable[[#This Row],[Currency]]="","Fail","Pass") -> Pass | S8: =IF( ValidationTable[[#This Row],[Currency]]="CHF", IF(ValidationTable[[#This Row],[Exchange_Rate]]<>1,"Fail","Pass"), IF(ValidationTable[[#This Row],[Exchange_Rate]]<=0,"Fail","Pass") ) -> Pass | T8: =IF(ValidationTable[[#This Row],[VAT_Applicable]]="Yes", IF( ROUND(ValidationTable[[#This Row],[Net_Amount]]*ValidationTable[[#This Row],[VAT_Rate]],2)<>ROUND(ValidationTable[[#This Row],[VAT_Amount]],2), "Fail", "Pass" ), IF( OR(ValidationTable[[#This Row],[VAT_Rate]]<>0,ValidationTable[[#This Row],[VAT_Amount]]<>0 ), "Fail", "Pass" ) ) -> Pass | U8: =IF(LEN(TRIM(ValidationTable[[#This Row],[Bank_Account]]))=0,"Fail","Pass") -> Pass | V8: =IF( COUNTIF(ValidationTable[Record_ID],ValidationTable[[#This Row],[Record_ID]])>1, "Fail", "Pass" ) -> Pass | W8: =IF( COUNTIF(ValidationTable[[#This Row],[RequiredField_Validation]]:ValidationTable[[#This Row],[Duplicate_Validation]],"Fail")>0, "Fail", "Pass" ) -> Pass | X8: =IF(ValidationTable[[#This Row],[Validation_Result]]="Pass","Yes","No") -> Yes
A9: =RawTable[[#This Row],[Record_ID]] -> 8 | B9: =RawTable[[#This Row],[Payment_Type]] -> Payroll | C9: =RawTable[[#This Row],[Entity_Type]] -> Employee | D9: =RawTable[[#This Row],[Country]] -> Germany | E9: =RawTable[[#This Row],[Name]] -> David Khan | F9: =RawTable[[#This Row],[Bank_Account]] -> DE890000000000122211 | G9: =RawTable[[#This Row],[Month]] -> Mar-2026 | H9: =RawTable[[#This Row],[Currency]] -> EUR | I9: =RawTable[[#This Row],[Net_Amount]] -> 6138.6 | J9: =RawTable[[#This Row],[VAT_Applicable]] -> No | K9: =RawTable[[#This Row],[VAT_Rate]] -> 0 | L9: =RawTable[[#This Row],[VAT_Amount]] -> 0 | M9: =RawTable[[#This Row],[Gross_Amount]] -> 6138.6 | N9: =RawTable[[#This Row],[Exchange_Rate]] -> 0.90888 | O9: =RawTable[[#This Row],[Amount_CHF]] -> 5579.25 | P9: =IF( OR(ValidationTable[[#This Row],[Record_ID]]="",ValidationTable[[#This Row],[Payment_Type]]="",ValidationTable[[#This Row],[Entity_Type]]="", ValidationTable[[#This Row],[Country]]="", ValidationTable[[#This Row],[Name]]="", ValidationTable[[#This Row],[Month]]="", ValidationTable[[#This Row],[Currency]]="" ), "Fail", "Pass" ) -> Pass | Q9: =IF( OR(ValidationTable[[#This Row],[Net_Amount]]<=0, ROUND(ValidationTable[[#This Row],[Net_Amount]]+ValidationTable[[#This Row],[VAT_Amount]],2)<>ROUND(ValidationTable[[#This Row],[Gross_Amount]],2) ), "Fail", "Pass" ) -> Pass | R9: =IF(ValidationTable[[#This Row],[Currency]]="","Fail","Pass") -> Pass | S9: =IF( ValidationTable[[#This Row],[Currency]]="CHF", IF(ValidationTable[[#This Row],[Exchange_Rate]]<>1,"Fail","Pass"), IF(ValidationTable[[#This Row],[Exchange_Rate]]<=0,"Fail","Pass") ) -> Pass | T9: =IF(ValidationTable[[#This Row],[VAT_Applicable]]="Yes", IF( ROUND(ValidationTable[[#This Row],[Net_Amount]]*ValidationTable[[#This Row],[VAT_Rate]],2)<>ROUND(ValidationTable[[#This Row],[VAT_Amount]],2), "Fail", "Pass" ), IF( OR(ValidationTable[[#This Row],[VAT_Rate]]<>0,ValidationTable[[#This Row],[VAT_Amount]]<>0 ), "Fail", "Pass" ) ) -> Pass | U9: =IF(LEN(TRIM(ValidationTable[[#This Row],[Bank_Account]]))=0,"Fail","Pass") -> Pass | V9: =IF( COUNTIF(ValidationTable[Record_ID],ValidationTable[[#This Row],[Record_ID]])>1, "Fail", "Pass" ) -> Pass | W9: =IF( COUNTIF(ValidationTable[[#This Row],[RequiredField_Validation]]:ValidationTable[[#This Row],[Duplicate_Validation]],"Fail")>0, "Fail", "Pass" ) -> Pass | X9: =IF(ValidationTable[[#This Row],[Validation_Result]]="Pass","Yes","No") -> Yes
A10: =RawTable[[#This Row],[Record_ID]] -> 9 | B10: =RawTable[[#This Row],[Payment_Type]] -> Payroll | C10: =RawTable[[#This Row],[Entity_Type]] -> Employee | D10: =RawTable[[#This Row],[Country]] -> USA | E10: =RawTable[[#This Row],[Name]] -> Lina Wilson | F10: =RawTable[[#This Row],[Bank_Account]] -> US-RT-000012340-AC-0000056780 | G10: =RawTable[[#This Row],[Month]] -> Mar-2026 | H10: =RawTable[[#This Row],[Currency]] -> USD | I10: =RawTable[[#This Row],[Net_Amount]] -> 7459.9 | J10: =RawTable[[#This Row],[VAT_Applicable]] -> No | K10: =RawTable[[#This Row],[VAT_Rate]] -> 0 | L10: =RawTable[[#This Row],[VAT_Amount]] -> 0 | M10: =RawTable[[#This Row],[Gross_Amount]] -> 7459.9 | N10: =RawTable[[#This Row],[Exchange_Rate]] -> 0.77018 | O10: =RawTable[[#This Row],[Amount_CHF]] -> 5745.47 | P10: =IF( OR(ValidationTable[[#This Row],[Record_ID]]="",ValidationTable[[#This Row],[Payment_Type]]="",ValidationTable[[#This Row],[Entity_Type]]="", ValidationTable[[#This Row],[Country]]="", ValidationTable[[#This Row],[Name]]="", ValidationTable[[#This Row],[Month]]="", ValidationTable[[#This Row],[Currency]]="" ), "Fail", "Pass" ) -> Pass | Q10: =IF( OR(ValidationTable[[#This Row],[Net_Amount]]<=0, ROUND(ValidationTable[[#This Row],[Net_Amount]]+ValidationTable[[#This Row],[VAT_Amount]],2)<>ROUND(ValidationTable[[#This Row],[Gross_Amount]],2) ), "Fail", "Pass" ) -> Pass | R10: =IF(ValidationTable[[#This Row],[Currency]]="","Fail","Pass") -> Pass | S10: =IF( ValidationTable[[#This Row],[Currency]]="CHF", IF(ValidationTable[[#This Row],[Exchange_Rate]]<>1,"Fail","Pass"), IF(ValidationTable[[#This Row],[Exchange_Rate]]<=0,"Fail","Pass") ) -> Pass | T10: =IF(ValidationTable[[#This Row],[VAT_Applicable]]="Yes", IF( ROUND(ValidationTable[[#This Row],[Net_Amount]]*ValidationTable[[#This Row],[VAT_Rate]],2)<>ROUND(ValidationTable[[#This Row],[VAT_Amount]],2), "Fail", "Pass" ), IF( OR(ValidationTable[[#This Row],[VAT_Rate]]<>0,ValidationTable[[#This Row],[VAT_Amount]]<>0 ), "Fail", "Pass" ) ) -> Pass | U10: =IF(LEN(TRIM(ValidationTable[[#This Row],[Bank_Account]]))=0,"Fail","Pass") -> Pass | V10: =IF( COUNTIF(ValidationTable[Record_ID],ValidationTable[[#This Row],[Record_ID]])>1, "Fail", "Pass" ) -> Pass | W10: =IF( COUNTIF(ValidationTable[[#This Row],[RequiredField_Validation]]:ValidationTable[[#This Row],[Duplicate_Validation]],"Fail")>0, "Fail", "Pass" ) -> Pass | X10: =IF(ValidationTable[[#This Row],[Validation_Result]]="Pass","Yes","No") -> Yes
A11: =RawTable[[#This Row],[Record_ID]] -> 10 | B11: =RawTable[[#This Row],[Payment_Type]] -> Payroll | C11: =RawTable[[#This Row],[Entity_Type]] -> Employee | D11: =RawTable[[#This Row],[Country]] -> USA | E11: =RawTable[[#This Row],[Name]] -> Michael Wilson | F11: =RawTable[[#This Row],[Bank_Account]] -> US-RT-000013574-AC-0000062458 | G11: =RawTable[[#This Row],[Month]] -> Mar-2026 | H11: =RawTable[[#This Row],[Currency]] -> USD | I11: =RawTable[[#This Row],[Net_Amount]] -> 7142.8 | J11: =RawTable[[#This Row],[VAT_Applicable]] -> No | K11: =RawTable[[#This Row],[VAT_Rate]] -> 0 | L11: =RawTable[[#This Row],[VAT_Amount]] -> 0 | M11: =RawTable[[#This Row],[Gross_Amount]] -> 7142.8 | N11: =RawTable[[#This Row],[Exchange_Rate]] -> 0.77018 | O11: =RawTable[[#This Row],[Amount_CHF]] -> 5501.24 | P11: =IF( OR(ValidationTable[[#This Row],[Record_ID]]="",ValidationTable[[#This Row],[Payment_Type]]="",ValidationTable[[#This Row],[Entity_Type]]="", ValidationTable[[#This Row],[Country]]="", ValidationTable[[#This Row],[Name]]="", ValidationTable[[#This Row],[Month]]="", ValidationTable[[#This Row],[Currency]]="" ), "Fail", "Pass" ) -> Pass | Q11: =IF( OR(ValidationTable[[#This Row],[Net_Amount]]<=0, ROUND(ValidationTable[[#This Row],[Net_Amount]]+ValidationTable[[#This Row],[VAT_Amount]],2)<>ROUND(ValidationTable[[#This Row],[Gross_Amount]],2) ), "Fail", "Pass" ) -> Pass | R11: =IF(ValidationTable[[#This Row],[Currency]]="","Fail","Pass") -> Pass | S11: =IF( ValidationTable[[#This Row],[Currency]]="CHF", IF(ValidationTable[[#This Row],[Exchange_Rate]]<>1,"Fail","Pass"), IF(ValidationTable[[#This Row],[Exchange_Rate]]<=0,"Fail","Pass") ) -> Pass | T11: =IF(ValidationTable[[#This Row],[VAT_Applicable]]="Yes", IF( ROUND(ValidationTable[[#This Row],[Net_Amount]]*ValidationTable[[#This Row],[VAT_Rate]],2)<>ROUND(ValidationTable[[#This Row],[VAT_Amount]],2), "Fail", "Pass" ), IF( OR(ValidationTable[[#This Row],[VAT_Rate]]<>0,ValidationTable[[#This Row],[VAT_Amount]]<>0 ), "Fail", "Pass" ) ) -> Pass | U11: =IF(LEN(TRIM(ValidationTable[[#This Row],[Bank_Account]]))=0,"Fail","Pass") -> Pass | V11: =IF( COUNTIF(ValidationTable[Record_ID],ValidationTable[[#This Row],[Record_ID]])>1, "Fail", "Pass" ) -> Pass | W11: =IF( COUNTIF(ValidationTable[[#This Row],[RequiredField_Validation]]:ValidationTable[[#This Row],[Duplicate_Validation]],"Fail")>0, "Fail", "Pass" ) -> Pass | X11: =IF(ValidationTable[[#This Row],[Validation_Result]]="Pass","Yes","No") -> Yes
A12: =RawTable[[#This Row],[Record_ID]] -> 11 | B12: =RawTable[[#This Row],[Payment_Type]] -> Payroll | C12: =RawTable[[#This Row],[Entity_Type]] -> Employee | D12: =RawTable[[#This Row],[Country]] -> Jordan | E12: =RawTable[[#This Row],[Name]] -> David Smith | F12: =RawTable[[#This Row],[Bank_Account]] -> JO-IBAN-00148140 | G12: =RawTable[[#This Row],[Month]] -> Feb-2026 | H12: =RawTable[[#This Row],[Currency]] -> JOD | I12: =RawTable[[#This Row],[Net_Amount]] -> 1971.72 | J12: =RawTable[[#This Row],[VAT_Applicable]] -> No | K12: =RawTable[[#This Row],[VAT_Rate]] -> 0 | L12: =RawTable[[#This Row],[VAT_Amount]] -> 0 | M12: =RawTable[[#This Row],[Gross_Amount]] -> 1971.72 | N12: =RawTable[[#This Row],[Exchange_Rate]] -> 1.08643 | O12: =RawTable[[#This Row],[Amount_CHF]] -> 2142.14 | P12: =IF( OR(ValidationTable[[#This Row],[Record_ID]]="",ValidationTable[[#This Row],[Payment_Type]]="",ValidationTable[[#This Row],[Entity_Type]]="", ValidationTable[[#This Row],[Country]]="", ValidationTable[[#This Row],[Name]]="", ValidationTable[[#This Row],[Month]]="", ValidationTable[[#This Row],[Currency]]="" ), "Fail", "Pass" ) -> Pass | Q12: =IF( OR(ValidationTable[[#This Row],[Net_Amount]]<=0, ROUND(ValidationTable[[#This Row],[Net_Amount]]+ValidationTable[[#This Row],[VAT_Amount]],2)<>ROUND(ValidationTable[[#This Row],[Gross_Amount]],2) ), "Fail", "Pass" ) -> Pass | R12: =IF(ValidationTable[[#This Row],[Currency]]="","Fail","Pass") -> Pass | S12: =IF( ValidationTable[[#This Row],[Currency]]="CHF", IF(ValidationTable[[#This Row],[Exchange_Rate]]<>1,"Fail","Pass"), IF(ValidationTable[[#This Row],[Exchange_Rate]]<=0,"Fail","Pass") ) -> Pass | T12: =IF(ValidationTable[[#This Row],[VAT_Applicable]]="Yes", IF( ROUND(ValidationTable[[#This Row],[Net_Amount]]*ValidationTable[[#This Row],[VAT_Rate]],2)<>ROUND(ValidationTable[[#This Row],[VAT_Amount]],2), "Fail", "Pass" ), IF( OR(ValidationTable[[#This Row],[VAT_Rate]]<>0,ValidationTable[[#This Row],[VAT_Amount]]<>0 ), "Fail", "Pass" ) ) -> Pass | U12: =IF(LEN(TRIM(ValidationTable[[#This Row],[Bank_Account]]))=0,"Fail","Pass") -> Pass | V12: =IF( COUNTIF(ValidationTable[Record_ID],ValidationTable[[#This Row],[Record_ID]])>1, "Fail", "Pass" ) -> Pass | W12: =IF( COUNTIF(ValidationTable[[#This Row],[RequiredField_Validation]]:ValidationTable[[#This Row],[Duplicate_Validation]],"Fail")>0, "Fail", "Pass" ) -> Pass | X12: =IF(ValidationTable[[#This Row],[Validation_Result]]="Pass","Yes","No") -> Yes
A13: =RawTable[[#This Row],[Record_ID]] -> 12 | B13: =RawTable[[#This Row],[Payment_Type]] -> Payroll | C13: =RawTable[[#This Row],[Entity_Type]] -> Employee | D13: =RawTable[[#This Row],[Country]] -> USA | E13: =RawTable[[#This Row],[Name]] -> Michael Wilson | F13: =RawTable[[#This Row],[Bank_Account]] -> US-RT-000013574-AC-0000062458 | G13: =RawTable[[#This Row],[Month]] -> Jan-2026 | H13: =RawTable[[#This Row],[Currency]] -> USD | I13: =RawTable[[#This Row],[Net_Amount]] -> 7249.94 | J13: =RawTable[[#This Row],[VAT_Applicable]] -> No | K13: =RawTable[[#This Row],[VAT_Rate]] -> 0 | L13: =RawTable[[#This Row],[VAT_Amount]] -> 0 | M13: =RawTable[[#This Row],[Gross_Amount]] -> 7249.94 | N13: =RawTable[[#This Row],[Exchange_Rate]] -> 0.77018 | O13: =RawTable[[#This Row],[Amount_CHF]] -> 5583.76 | P13: =IF( OR(ValidationTable[[#This Row],[Record_ID]]="",ValidationTable[[#This Row],[Payment_Type]]="",ValidationTable[[#This Row],[Entity_Type]]="", ValidationTable[[#This Row],[Country]]="", ValidationTable[[#This Row],[Name]]="", ValidationTable[[#This Row],[Month]]="", ValidationTable[[#This Row],[Currency]]="" ), "Fail", "Pass" ) -> Pass | Q13: =IF( OR(ValidationTable[[#This Row],[Net_Amount]]<=0, ROUND(ValidationTable[[#This Row],[Net_Amount]]+ValidationTable[[#This Row],[VAT_Amount]],2)<>ROUND(ValidationTable[[#This Row],[Gross_Amount]],2) ), "Fail", "Pass" ) -> Pass | R13: =IF(ValidationTable[[#This Row],[Currency]]="","Fail","Pass") -> Pass | S13: =IF( ValidationTable[[#This Row],[Currency]]="CHF", IF(ValidationTable[[#This Row],[Exchange_Rate]]<>1,"Fail","Pass"), IF(ValidationTable[[#This Row],[Exchange_Rate]]<=0,"Fail","Pass") ) -> Pass | T13: =IF(ValidationTable[[#This Row],[VAT_Applicable]]="Yes", IF( ROUND(ValidationTable[[#This Row],[Net_Amount]]*ValidationTable[[#This Row],[VAT_Rate]],2)<>ROUND(ValidationTable[[#This Row],[VAT_Amount]],2), "Fail", "Pass" ), IF( OR(ValidationTable[[#This Row],[VAT_Rate]]<>0,ValidationTable[[#This Row],[VAT_Amount]]<>0 ), "Fail", "Pass" ) ) -> Pass | U13: =IF(LEN(TRIM(ValidationTable[[#This Row],[Bank_Account]]))=0,"Fail","Pass") -> Pass | V13: =IF( COUNTIF(ValidationTable[Record_ID],ValidationTable[[#This Row],[Record_ID]])>1, "Fail", "Pass" ) -> Pass | W13: =IF( COUNTIF(ValidationTable[[#This Row],[RequiredField_Validation]]:ValidationTable[[#This Row],[Duplicate_Validation]],"Fail")>0, "Fail", "Pass" ) -> Pass | X13: =IF(ValidationTable[[#This Row],[Validation_Result]]="Pass","Yes","No") -> Yes
... A132: =RawTable[[#This Row],[Record_ID]] -> 131 | B132: =RawTable[[#This Row],[Payment_Type]] -> Payroll | C132: =RawTable[[#This Row],[Entity_Type]] -> Employee | D132: =RawTable[[#This Row],[Country]] -> USA | E132: =RawTable[[#This Row],[Name]] -> John Müller | F132: =RawTable[[#This Row],[Bank_Account]] -> CH930000000001382080 | G132: =RawTable[[#This Row],[Month]] -> Mar-2026 | H132: =RawTable[[#This Row],[Currency]] -> USD | I132: =RawTable[[#This Row],[Net_Amount]] -> 6871.25 | J132: =RawTable[[#This Row],[VAT_Applicable]] -> No | K132: =RawTable[[#This Row],[VAT_Rate]] -> 0 | L132: =RawTable[[#This Row],[VAT_Amount]] -> 0 | M132: =RawTable[[#This Row],[Gross_Amount]] -> 6871.25 | N132: =RawTable[[#This Row],[Exchange_Rate]] -> 0.77018 | O132: =RawTable[[#This Row],[Amount_CHF]] -> 5292.1 | P132: =IF( OR(ValidationTable[[#This Row],[Record_ID]]="",ValidationTable[[#This Row],[Payment_Type]]="",ValidationTable[[#This Row],[Entity_Type]]="", ValidationTable[[#This Row],[Country]]="", ValidationTable[[#This Row],[Name]]="", ValidationTable[[#This Row],[Month]]="", ValidationTable[[#This Row],[Currency]]="" ), "Fail", "Pass" ) -> Pass | Q132: =IF( OR(ValidationTable[[#This Row],[Net_Amount]]<=0, ROUND(ValidationTable[[#This Row],[Net_Amount]]+ValidationTable[[#This Row],[VAT_Amount]],2)<>ROUND(ValidationTable[[#This Row],[Gross_Amount]],2) ), "Fail", "Pass" ) -> Pass | R132: =IF(ValidationTable[[#This Row],[Currency]]="","Fail","Pass") -> Pass | S132: =IF( ValidationTable[[#This Row],[Currency]]="CHF", IF(ValidationTable[[#This Row],[Exchange_Rate]]<>1,"Fail","Pass"), IF(ValidationTable[[#This Row],[Exchange_Rate]]<=0,"Fail","Pass") ) -> Pass | T132: =IF(ValidationTable[[#This Row],[VAT_Applicable]]="Yes", IF( ROUND(ValidationTable[[#This Row],[Net_Amount]]*ValidationTable[[#This Row],[VAT_Rate]],2)<>ROUND(ValidationTable[[#This Row],[VAT_Amount]],2), "Fail", "Pass" ), IF( OR(ValidationTable[[#This Row],[VAT_Rate]]<>0,ValidationTable[[#This Row],[VAT_Amount]]<>0 ), "Fail", "Pass" ) ) -> Pass | U132: =IF(LEN(TRIM(ValidationTable[[#This Row],[Bank_Account]]))=0,"Fail","Pass") -> Pass | V132: =IF( COUNTIF(ValidationTable[Record_ID],ValidationTable[[#This Row],[Record_ID]])>1, "Fail", "Pass" ) -> Pass | W132: =IF( COUNTIF(ValidationTable[[#This Row],[RequiredField_Validation]]:ValidationTable[[#This Row],[Duplicate_Validation]],"Fail")>0, "Fail", "Pass" ) -> Pass | X132: =IF(ValidationTable[[#This Row],[Validation_Result]]="Pass","Yes","No") -> Yes
A133: =RawTable[[#This Row],[Record_ID]] -> 132 | B133: =RawTable[[#This Row],[Payment_Type]] -> Payroll | C133: =RawTable[[#This Row],[Entity_Type]] -> Employee | D133: =RawTable[[#This Row],[Country]] -> USA | E133: =RawTable[[#This Row],[Name]] -> John Taylor | F133: =RawTable[[#This Row],[Bank_Account]] -> US-RT-000085146-AC-0000391782 | G133: =RawTable[[#This Row],[Month]] -> Jan-2026 | I133: =RawTable[[#This Row],[Net_Amount]] -> 6836.9 | J133: =RawTable[[#This Row],[VAT_Applicable]] -> No | K133: =RawTable[[#This Row],[VAT_Rate]] -> 0 | L133: =RawTable[[#This Row],[VAT_Amount]] -> 0 | M133: =RawTable[[#This Row],[Gross_Amount]] -> 6836.9 | N133: =RawTable[[#This Row],[Exchange_Rate]] | O133: =RawTable[[#This Row],[Amount_CHF]] | P133: =IF( OR(ValidationTable[[#This Row],[Record_ID]]="",ValidationTable[[#This Row],[Payment_Type]]="",ValidationTable[[#This Row],[Entity_Type]]="", ValidationTable[[#This Row],[Country]]="", ValidationTable[[#This Row],[Name]]="", ValidationTable[[#This Row],[Month]]="", ValidationTable[[#This Row],[Currency]]="" ), "Fail", "Pass" ) -> Fail | Q133: =IF( OR(ValidationTable[[#This Row],[Net_Amount]]<=0, ROUND(ValidationTable[[#This Row],[Net_Amount]]+ValidationTable[[#This Row],[VAT_Amount]],2)<>ROUND(ValidationTable[[#This Row],[Gross_Amount]],2) ), "Fail", "Pass" ) -> Pass | R133: =IF(ValidationTable[[#This Row],[Currency]]="","Fail","Pass") -> Fail | S133: =IF( ValidationTable[[#This Row],[Currency]]="CHF", IF(ValidationTable[[#This Row],[Exchange_Rate]]<>1,"Fail","Pass"), IF(ValidationTable[[#This Row],[Exchange_Rate]]<=0,"Fail","Pass") ) -> Pass | T133: =IF(ValidationTable[[#This Row],[VAT_Applicable]]="Yes", IF( ROUND(ValidationTable[[#This Row],[Net_Amount]]*ValidationTable[[#This Row],[VAT_Rate]],2)<>ROUND(ValidationTable[[#This Row],[VAT_Amount]],2), "Fail", "Pass" ), IF( OR(ValidationTable[[#This Row],[VAT_Rate]]<>0,ValidationTable[[#This Row],[VAT_Amount]]<>0 ), "Fail", "Pass" ) ) -> Pass | U133: =IF(LEN(TRIM(ValidationTable[[#This Row],[Bank_Account]]))=0,"Fail","Pass") -> Pass | V133: =IF( COUNTIF(ValidationTable[Record_ID],ValidationTable[[#This Row],[Record_ID]])>1, "Fail", "Pass" ) -> Pass | W133: =IF( COUNTIF(ValidationTable[[#This Row],[RequiredField_Validation]]:ValidationTable[[#This Row],[Duplicate_Validation]],"Fail")>0, "Fail", "Pass" ) -> Fail | X133: =IF(ValidationTable[[#This Row],[Validation_Result]]="Pass","Yes","No") -> No
A134: =RawTable[[#This Row],[Record_ID]] -> 133 | B134: =RawTable[[#This Row],[Payment_Type]] -> Payroll | C134: =RawTable[[#This Row],[Entity_Type]] -> Employee | D134: =RawTable[[#This Row],[Country]] -> Jordan | E134: =RawTable[[#This Row],[Name]] -> Michael Taylor | F134: =RawTable[[#This Row],[Bank_Account]] -> US-RT-000024680-AC-0000113560 | G134: =RawTable[[#This Row],[Month]] -> Jan-2026 | H134: =RawTable[[#This Row],[Currency]] -> JOD | I134: =RawTable[[#This Row],[Net_Amount]] -> 1919.34 | J134: =RawTable[[#This Row],[VAT_Applicable]] -> No | K134: =RawTable[[#This Row],[VAT_Rate]] -> 0 | L134: =RawTable[[#This Row],[VAT_Amount]] -> 0 | M134: =RawTable[[#This Row],[Gross_Amount]] -> 1919.34 | N134: =RawTable[[#This Row],[Exchange_Rate]] -> 1.08643 | O134: =RawTable[[#This Row],[Amount_CHF]] -> 2085.23 | P134: =IF( OR(ValidationTable[[#This Row],[Record_ID]]="",ValidationTable[[#This Row],[Payment_Type]]="",ValidationTable[[#This Row],[Entity_Type]]="", ValidationTable[[#This Row],[Country]]="", ValidationTable[[#This Row],[Name]]="", ValidationTable[[#This Row],[Month]]="", ValidationTable[[#This Row],[Currency]]="" ), "Fail", "Pass" ) -> Pass | Q134: =IF( OR(ValidationTable[[#This Row],[Net_Amount]]<=0, ROUND(ValidationTable[[#This Row],[Net_Amount]]+ValidationTable[[#This Row],[VAT_Amount]],2)<>ROUND(ValidationTable[[#This Row],[Gross_Amount]],2) ), "Fail", "Pass" ) -> Pass | R134: =IF(ValidationTable[[#This Row],[Currency]]="","Fail","Pass") -> Pass | S134: =IF( ValidationTable[[#This Row],[Currency]]="CHF", IF(ValidationTable[[#This Row],[Exchange_Rate]]<>1,"Fail","Pass"), IF(ValidationTable[[#This Row],[Exchange_Rate]]<=0,"Fail","Pass") ) -> Pass | T134: =IF(ValidationTable[[#This Row],[VAT_Applicable]]="Yes", IF( ROUND(ValidationTable[[#This Row],[Net_Amount]]*ValidationTable[[#This Row],[VAT_Rate]],2)<>ROUND(ValidationTable[[#This Row],[VAT_Amount]],2), "Fail", "Pass" ), IF( OR(ValidationTable[[#This Row],[VAT_Rate]]<>0,ValidationTable[[#This Row],[VAT_Amount]]<>0 ), "Fail", "Pass" ) ) -> Pass | U134: =IF(LEN(TRIM(ValidationTable[[#This Row],[Bank_Account]]))=0,"Fail","Pass") -> Pass | V134: =IF( COUNTIF(ValidationTable[Record_ID],ValidationTable[[#This Row],[Record_ID]])>1, "Fail", "Pass" ) -> Pass | W134: =IF( COUNTIF(ValidationTable[[#This Row],[RequiredField_Validation]]:ValidationTable[[#This Row],[Duplicate_Validation]],"Fail")>0, "Fail", "Pass" ) -> Pass | X134: =IF(ValidationTable[[#This Row],[Validation_Result]]="Pass","Yes","No") -> Yes
A135: =RawTable[[#This Row],[Record_ID]] -> 134 | B135: =RawTable[[#This Row],[Payment_Type]] -> Payroll | C135: =RawTable[[#This Row],[Entity_Type]] -> Employee | D135: =RawTable[[#This Row],[Country]] -> Jordan | E135: =RawTable[[#This Row],[Name]] -> Omar Khan | F135: =RawTable[[#This Row],[Bank_Account]] -> AE-IBAN-01738272 | G135: =RawTable[[#This Row],[Month]] -> Jan-2026 | H135: =RawTable[[#This Row],[Currency]] -> JOD | I135: =RawTable[[#This Row],[Net_Amount]] -> 1697.58 | J135: =RawTable[[#This Row],[VAT_Applicable]] -> No | K135: =RawTable[[#This Row],[VAT_Rate]] -> 0 | L135: =RawTable[[#This Row],[VAT_Amount]] -> 0 | M135: =RawTable[[#This Row],[Gross_Amount]] -> 1697.58 | N135: =RawTable[[#This Row],[Exchange_Rate]] -> 1.08643 | O135: =RawTable[[#This Row],[Amount_CHF]] -> 1844.3 | P135: =IF( OR(ValidationTable[[#This Row],[Record_ID]]="",ValidationTable[[#This Row],[Payment_Type]]="",ValidationTable[[#This Row],[Entity_Type]]="", ValidationTable[[#This Row],[Country]]="", ValidationTable[[#This Row],[Name]]="", ValidationTable[[#This Row],[Month]]="", ValidationTable[[#This Row],[Currency]]="" ), "Fail", "Pass" ) -> Pass | Q135: =IF( OR(ValidationTable[[#This Row],[Net_Amount]]<=0, ROUND(ValidationTable[[#This Row],[Net_Amount]]+ValidationTable[[#This Row],[VAT_Amount]],2)<>ROUND(ValidationTable[[#This Row],[Gross_Amount]],2) ), "Fail", "Pass" ) -> Pass | R135: =IF(ValidationTable[[#This Row],[Currency]]="","Fail","Pass") -> Pass | S135: =IF( ValidationTable[[#This Row],[Currency]]="CHF", IF(ValidationTable[[#This Row],[Exchange_Rate]]<>1,"Fail","Pass"), IF(ValidationTable[[#This Row],[Exchange_Rate]]<=0,"Fail","Pass") ) -> Pass | T135: =IF(ValidationTable[[#This Row],[VAT_Applicable]]="Yes", IF( ROUND(ValidationTable[[#This Row],[Net_Amount]]*ValidationTable[[#This Row],[VAT_Rate]],2)<>ROUND(ValidationTable[[#This Row],[VAT_Amount]],2), "Fail", "Pass" ), IF( OR(ValidationTable[[#This Row],[VAT_Rate]]<>0,ValidationTable[[#This Row],[VAT_Amount]]<>0 ), "Fail", "Pass" ) ) -> Pass | U135: =IF(LEN(TRIM(ValidationTable[[#This Row],[Bank_Account]]))=0,"Fail","Pass") -> Pass | V135: =IF( COUNTIF(ValidationTable[Record_ID],ValidationTable[[#This Row],[Record_ID]])>1, "Fail", "Pass" ) -> Pass | W135: =IF( COUNTIF(ValidationTable[[#This Row],[RequiredField_Validation]]:ValidationTable[[#This Row],[Duplicate_Validation]],"Fail")>0, "Fail", "Pass" ) -> Pass | X135: =IF(ValidationTable[[#This Row],[Validation_Result]]="Pass","Yes","No") -> Yes
A136: =RawTable[[#This Row],[Record_ID]] -> 135 | B136: =RawTable[[#This Row],[Payment_Type]] -> Payroll | C136: =RawTable[[#This Row],[Entity_Type]] -> Employee | D136: =RawTable[[#This Row],[Country]] -> USA | E136: =RawTable[[#This Row],[Name]] -> Michael Taylor | F136: =RawTable[[#This Row],[Bank_Account]] -> US-RT-000024680-AC-0000113560 | G136: =RawTable[[#This Row],[Month]] -> Jan-2026 | H136: =RawTable[[#This Row],[Currency]] -> USD | I136: =RawTable[[#This Row],[Net_Amount]] -> 7689.7 | J136: =RawTable[[#This Row],[VAT_Applicable]] -> No | K136: =RawTable[[#This Row],[VAT_Rate]] -> 0 | L136: =RawTable[[#This Row],[VAT_Amount]] -> 0 | M136: =RawTable[[#This Row],[Gross_Amount]] -> 7689.7 | N136: =RawTable[[#This Row],[Exchange_Rate]] -> 0.77018 | O136: =RawTable[[#This Row],[Amount_CHF]] -> 5922.45 | P136: =IF( OR(ValidationTable[[#This Row],[Record_ID]]="",ValidationTable[[#This Row],[Payment_Type]]="",ValidationTable[[#This Row],[Entity_Type]]="", ValidationTable[[#This Row],[Country]]="", ValidationTable[[#This Row],[Name]]="", ValidationTable[[#This Row],[Month]]="", ValidationTable[[#This Row],[Currency]]="" ), "Fail", "Pass" ) -> Pass | Q136: =IF( OR(ValidationTable[[#This Row],[Net_Amount]]<=0, ROUND(ValidationTable[[#This Row],[Net_Amount]]+ValidationTable[[#This Row],[VAT_Amount]],2)<>ROUND(ValidationTable[[#This Row],[Gross_Amount]],2) ), "Fail", "Pass" ) -> Pass | R136: =IF(ValidationTable[[#This Row],[Currency]]="","Fail","Pass") -> Pass | S136: =IF( ValidationTable[[#This Row],[Currency]]="CHF", IF(ValidationTable[[#This Row],[Exchange_Rate]]<>1,"Fail","Pass"), IF(ValidationTable[[#This Row],[Exchange_Rate]]<=0,"Fail","Pass") ) -> Pass | T136: =IF(ValidationTable[[#This Row],[VAT_Applicable]]="Yes", IF( ROUND(ValidationTable[[#This Row],[Net_Amount]]*ValidationTable[[#This Row],[VAT_Rate]],2)<>ROUND(ValidationTable[[#This Row],[VAT_Amount]],2), "Fail", "Pass" ), IF( OR(ValidationTable[[#This Row],[VAT_Rate]]<>0,ValidationTable[[#This Row],[VAT_Amount]]<>0 ), "Fail", "Pass" ) ) -> Pass | U136: =IF(LEN(TRIM(ValidationTable[[#This Row],[Bank_Account]]))=0,"Fail","Pass") -> Pass | V136: =IF( COUNTIF(ValidationTable[Record_ID],ValidationTable[[#This Row],[Record_ID]])>1, "Fail", "Pass" ) -> Pass | W136: =IF( COUNTIF(ValidationTable[[#This Row],[RequiredField_Validation]]:ValidationTable[[#This Row],[Duplicate_Validation]],"Fail")>0, "Fail", "Pass" ) -> Pass | X136: =IF(ValidationTable[[#This Row],[Validation_Result]]="Pass","Yes","No") -> Yes
