Workbook

Sheet Customers
A1: CustomerID | B1: CustomerName | C1: Industry | D1: Country | E1: PaymentTerms | F1: CreditLimit | G1: CustomerSince
A2: CUST-001 | B2: BrightCart | C2: E-commerce | D2: USA | E2: Net 60 | F2: 30000 | G2: 45691
A3: CUST-002 | B3: NexaSoft | C3: SaaS | D3: UK | E3: Net 60 | F3: 10000 | G3: 45912
A4: CUST-003 | B4: UrbanRetail | C4: Education | D4: USA | E4: Net 60 | F4: 50000 | G4: 45582
A5: CUST-004 | B5: LaunchLabs | C5: E-commerce | D5: USA | E5: Net 30 | F5: 20000 | G5: 45824
A6: CUST-005 | B6: DataHive | C6: Education | D6: USA | E6: Net 60 | F6: 20000 | G6: 45932
A7: CUST-006 | B7: ShopOrbit | C7: Education | D7: UAE | E7: Net 30 | F7: 50000 | G7: 45867
A8: CUST-007 | B8: EduNova | C8: Retail | D8: USA | E8: Net 30 | F8: 50000 | G8: 45740
A9: CUST-008 | B9: MarketPulse | C9: Retail | D9: UK | E9: Net 30 | F9: 30000 | G9: 45618
A10: CUST-009 | B10: CloudScale | C10: E-commerce | D10: UAE | E10: Net 30 | F10: 30000 | G10: 45999
A11: CUST-010 | B11: RetailHub | C11: Retail | D11: Canada | E11: Net 45 | F11: 10000 | G11: 45939
A12: CUST-011 | B12: AlphaCommerce | C12: Startup | D12: Canada | E12: Net 30 | F12: 50000 | G12: 45606
A13: CUST-012 | B13: BluePeak Systems | C13: Education | D13: Germany | E13: Net 60 | F13: 30000 | G13: 45861
... A119: CUST-118 | B119: RetailOrbitGlobal | C119: E-commerce | D119: UAE | E119: Net 30 | F119: 20000 | G119: 45977

Sheet Vendors
A1: VendorID | B1: VendorName | C1: Category | D1: Country | E1: PaymentTerms | F1: VendorSince
A2: VEN-001 | B2: Google Ads | C2: Consulting | D2: USA | E2: Net 60 | F2: 45693
A3: VEN-002 | B3: Meta Ads | C3: Freelancer | D3: UAE | E3: Net 30 | F3: 45976
A4: VEN-003 | B4: TikTok Ads | C4: Consulting | D4: Australia | E4: Net 60 | F4: 45852
A5: VEN-004 | B5: LinkedIn Ads | C5: Software | D5: UAE | E5: Net 60 | F5: 45983
A6: VEN-005 | B6: HubSpot | C6: Consulting | D6: Canada | E6: Net 45 | F6: 45647
A7: VEN-006 | B7: Salesforce | C7: Consulting | D7: UAE | E7: Net 45 | F7: 45950
A8: VEN-007 | B8: Mailchimp | C8: Advertising | D8: Australia | E8: Net 45 | F8: 45958
A9: VEN-008 | B9: Ahrefs | C9: Consulting | D9: Australia | E9: Net 30 | F9: 45706
A10: VEN-009 | B10: SEMrush | C10: Consulting | D10: USA | E10: Net 60 | F10: 45712
A11: VEN-010 | B11: Adobe Creative Cloud | C11: Advertising | D11: Germany | E11: Net 45 | F11: 45729
A12: VEN-011 | B12: AWS | C12: Freelancer | D12: UK | E12: Net 30 | F12: 45684
A13: VEN-012 | B13: Google Cloud | C13: Consulting | D13: Australia | E13: Net 30 | F13: 45927
... A41: VEN-040 | B41: Digital Performance Lab | C41: Consulting | D41: UAE | E41: Net 60 | F41: 45667

Sheet Services
A1: ServiceID | B1: ServiceName | C1: StandardPrice | D1: EstimatedCost
A2: SER-001 | B2: SEO Management | C2: 3000 | D2: 1200
A3: SER-002 | B3: Paid Ads Management | C3: 5000 | D3: 2200
A4: SER-003 | B4: Social Media Marketing | C4: 2500 | D4: 900
A5: SER-004 | B5: Website Development | C5: 12000 | D5: 6500
A6: SER-005 | B6: Content Marketing | C6: 3500 | D6: 1500
A7: SER-006 | B7: Email Marketing | C7: 1800 | D7: 700

Sheet Sales_Invoices
A1: InvoiceID | B1: CustomerID | C1: ServiceID | D1: InvoiceDate | E1: DueDate | F1: TotalAmount | G1: Status
A2: INV-00001 | B2: CUST-090 | C2: SER-001 | D2: 46097 | E2: 46127 | F2: 3110.52 | G2: Paid
A3: INV-00002 | B3: CUST-073 | C3: SER-003 | D3: 45987 | E3: 46017 | F3: 2850.29 | G3: Open
A4: INV-00003 | B4: CUST-065 | C4: SER-001 | D4: 46094 | E4: 46124 | F4: 2816.64 | G4: Paid
A5: INV-00004 | B5: CUST-014 | C5: SER-006 | D5: 45971 | E5: 46001 | F5: 1685.69 | G5: Open
A6: INV-00005 | B6: CUST-056 | C6: SER-004 | D6: 46099 | E6: 46129 | F6: 14211.78 | G6: Paid
A7: INV-00006 | B7: CUST-118 | C7: SER-002 | D7: 45982 | E7: 46012 | F7: 5467.59 | G7: Paid
A8: INV-00007 | B8: CUST-076 | C8: SER-005 | D8: 46074 | E8: 46104 | F8: 3884.5 | G8: Open
A9: INV-00008 | B9: CUST-058 | C9: SER-003 | D9: 46047 | E9: 46077 | F9: 2322.3 | G9: Paid
A10: INV-00009 | B10: CUST-044 | C10: SER-002 | D10: 46096 | E10: 46126 | F10: 5500.95 | G10: Paid
A11: INV-00010 | B11: CUST-046 | C11: SER-001 | D11: 46009 | E11: 46039 | F11: 2993.17 | G11: Paid
A12: INV-00011 | B12: CUST-036 | C12: SER-003 | D12: 46008 | E12: 46038 | F12: 2340.34 | G12: Paid
A13: INV-00012 | B13: CUST-053 | C13: SER-005 | D13: 46008 | E13: 46038 | F13: 2814.21 | G13: Paid
... A2801: INV-02800 | B2801: CUST-009 | C2801: SER-005 | D2801: 46083 | E2801: 46113 | F2801: 2878.2 | G2801: Paid

Sheet Customer_Payments
A1: PaymentID | B1: InvoiceID | C1: CustomerID | D1: PaymentDate | E1: PaymentAmount | F1: Method
A2: PAY-00001 | B2: INV-00001 | C2: CUST-090 | D2: 46091 | E2: 3110.52 | F2: Credit Card
A3: PAY-00002 | B3: INV-00003 | C3: CUST-065 | D3: 45887 | E3: 2816.64 | F3: Credit Card
A4: PAY-00003 | B4: INV-00005 | C4: CUST-056 | D4: 46006 | E4: 14211.78 | F4: Stripe
A5: PAY-00004 | B5: INV-00006 | C5: CUST-118 | D5: 46017 | E5: 5467.59 | F5: Stripe
A6: PAY-00005 | B6: INV-00008 | C6: CUST-058 | D6: 45798 | E6: 2322.3 | F6: PayPal
A7: PAY-00006 | B7: INV-00009 | C7: CUST-044 | D7: 45982 | E7: 5500.95 | F7: PayPal
A8: PAY-00007 | B8: INV-00010 | C8: CUST-046 | D8: 45836 | E8: 2993.17 | F8: Credit Card
A9: PAY-00008 | B9: INV-00011 | C9: CUST-036 | D9: 46113 | E9: 2340.34 | F9: Credit Card
A10: PAY-00009 | B10: INV-00012 | C10: CUST-053 | D10: 45758 | E10: 2814.21 | F10: Stripe
A11: PAY-00010 | B11: INV-00013 | C11: CUST-092 | D11: 45784 | E11: 12264.85 | F11: Bank Transfer
A12: PAY-00011 | B12: INV-00014 | C12: CUST-052 | D12: 45673 | E12: 7672.01 | F12: PayPal
A13: PAY-00012 | B13: INV-00014 | C13: CUST-052 | D13: 45674 | E13: 4079.23 | F13: Bank Transfer
... A2242: PAY-02241 | B2242: INV-02800 | C2242: CUST-009 | D2242: 46075 | E2242: 2878.2 | F2242: Bank Transfer

Sheet AR_Aging
A1: CustomerID | B1: CustomerName | C1: InvoiceID | D1: InvoiceDate | E1: DueDate | F1: InvoiceAmount | G1: AmountPaid | H1: OutstandingAmount | I1: DaysOutstanding | J1: AgingBucket
A2: CUST-090 | B2: =VLOOKUP(A2,Customers!A:B,2,FALSE) -> RetailLabs | C2: INV-00001 | D2: 46097 | E2: 46127 | F2: 3110.52 | G2: =SUMIF(Customer_Payments!B:B,C2,Customer_Payments!E:E) -> 3110.52 | H2: =MAX(F2-G2,0) -> 0 | I2: =$L$2-E2 -> -36 | J2: =IF(I2<=0,"Current", IF(I2<=30,"1-30", IF(I2<=60,"31-60", IF(I2<=90,"61-90","90+")))) -> Current | L2: 46091
A3: CUST-073 | B3: =VLOOKUP(A3,Customers!A:B,2,FALSE) -> RetailBoostX | C3: INV-00002 | D3: 45987 | E3: 46017 | F3: 2850.29 | G3: 2000 | H3: =MAX(F3-G3,0) -> 850.29 | I3: =$L$2-E3 -> 74 | J3: =IF(I3<=0,"Current", IF(I3<=30,"1-30", IF(I3<=60,"31-60", IF(I3<=90,"61-90","90+")))) -> 61-90
A4: CUST-065 | B4: =VLOOKUP(A4,Customers!A:B,2,FALSE) -> RetailPulse | C4: INV-00003 | D4: 46094 | E4: 46124 | F4: 2816.64 | G4: =SUMIF(Customer_Payments!B:B,C4,Customer_Payments!E:E) -> 2816.64 | H4: =MAX(F4-G4,0) -> 0 | I4: =$L$2-E4 -> -33 | J4: =IF(I4<=0,"Current", IF(I4<=30,"1-30", IF(I4<=60,"31-60", IF(I4<=90,"61-90","90+")))) -> Current
A5: CUST-014 | B5: =VLOOKUP(A5,Customers!A:B,2,FALSE) -> GrowthSphere | C5: INV-00004 | D5: 45971 | E5: 46001 | F5: 1685.69 | G5: =SUMIF(Customer_Payments!B:B,C5,Customer_Payments!E:E) -> 0 | H5: =MAX(F5-G5,0) -> 1685.69 | I5: =$L$2-E5 -> 90 | J5: =IF(I5<=0,"Current", IF(I5<=30,"1-30", IF(I5<=60,"31-60", IF(I5<=90,"61-90","90+")))) -> 61-90
A6: CUST-056 | B6: =VLOOKUP(A6,Customers!A:B,2,FALSE) -> MarketNova | C6: INV-00005 | D6: 46099 | E6: 46129 | F6: 14211.78 | G6: =SUMIF(Customer_Payments!B:B,C6,Customer_Payments!E:E) -> 14211.78 | H6: =MAX(F6-G6,0) -> 0 | I6: =$L$2-E6 -> -38 | J6: =IF(I6<=0,"Current", IF(I6<=30,"1-30", IF(I6<=60,"31-60", IF(I6<=90,"61-90","90+")))) -> Current
A7: CUST-118 | B7: =VLOOKUP(A7,Customers!A:B,2,FALSE) -> RetailOrbitGlobal | C7: INV-00006 | D7: 45982 | E7: 46012 | F7: 5467.59 | G7: =SUMIF(Customer_Payments!B:B,C7,Customer_Payments!E:E) -> 5467.59 | H7: =MAX(F7-G7,0) -> 0 | I7: =$L$2-E7 -> 79 | J7: =IF(I7<=0,"Current", IF(I7<=30,"1-30", IF(I7<=60,"31-60", IF(I7<=90,"61-90","90+")))) -> 61-90
A8: CUST-076 | B8: =VLOOKUP(A8,Customers!A:B,2,FALSE) -> RetailNovaX | C8: INV-00007 | D8: 46074 | E8: 46104 | F8: 3884.5 | G8: =SUMIF(Customer_Payments!B:B,C8,Customer_Payments!E:E) -> 0 | H8: =MAX(F8-G8,0) -> 3884.5 | I8: =$L$2-E8 -> -13 | J8: =IF(I8<=0,"Current", IF(I8<=30,"1-30", IF(I8<=60,"31-60", IF(I8<=90,"61-90","90+")))) -> Current
A9: CUST-058 | B9: =VLOOKUP(A9,Customers!A:B,2,FALSE) -> MarketScale | C9: INV-00008 | D9: 46047 | E9: 46077 | F9: 2322.3 | G9: =SUMIF(Customer_Payments!B:B,C9,Customer_Payments!E:E) -> 2322.3 | H9: =MAX(F9-G9,0) -> 0 | I9: =$L$2-E9 -> 14 | J9: =IF(I9<=0,"Current", IF(I9<=30,"1-30", IF(I9<=60,"31-60", IF(I9<=90,"61-90","90+")))) -> 1-30
A10: CUST-044 | B10: =VLOOKUP(A10,Customers!A:B,2,FALSE) -> RetailNexus | C10: INV-00009 | D10: 46096 | E10: 46126 | F10: 5500.95 | G10: =SUMIF(Customer_Payments!B:B,C10,Customer_Payments!E:E) -> 5500.95 | H10: =MAX(F10-G10,0) -> 0 | I10: =$L$2-E10 -> -35 | J10: =IF(I10<=0,"Current", IF(I10<=30,"1-30", IF(I10<=60,"31-60", IF(I10<=90,"61-90","90+")))) -> Current
A11: CUST-046 | B11: =VLOOKUP(A11,Customers!A:B,2,FALSE) -> RetailShift | C11: INV-00010 | D11: 46009 | E11: 46039 | F11: 2993.17 | G11: =SUMIF(Customer_Payments!B:B,C11,Customer_Payments!E:E) -> 2993.17 | H11: =MAX(F11-G11,0) -> 0 | I11: =$L$2-E11 -> 52 | J11: =IF(I11<=0,"Current", IF(I11<=30,"1-30", IF(I11<=60,"31-60", IF(I11<=90,"61-90","90+")))) -> 31-60
A12: CUST-036 | B12: =VLOOKUP(A12,Customers!A:B,2,FALSE) -> RetailWorks | C12: INV-00011 | D12: 46008 | E12: 46038 | F12: 2340.34 | G12: =SUMIF(Customer_Payments!B:B,C12,Customer_Payments!E:E) -> 2340.34 | H12: =MAX(F12-G12,0) -> 0 | I12: =$L$2-E12 -> 53 | J12: =IF(I12<=0,"Current", IF(I12<=30,"1-30", IF(I12<=60,"31-60", IF(I12<=90,"61-90","90+")))) -> 31-60
A13: CUST-053 | B13: =VLOOKUP(A13,Customers!A:B,2,FALSE) -> MarketBridge | C13: INV-00012 | D13: 46008 | E13: 46038 | F13: 2814.21 | G13: =SUMIF(Customer_Payments!B:B,C13,Customer_Payments!E:E) -> 2814.21 | H13: =MAX(F13-G13,0) -> 0 | I13: =$L$2-E13 -> 53 | J13: =IF(I13<=0,"Current", IF(I13<=30,"1-30", IF(I13<=60,"31-60", IF(I13<=90,"61-90","90+")))) -> 31-60
A14: CUST-092 | B14: =VLOOKUP(A14,Customers!A:B,2,FALSE) -> RetailEdgePro | C14: INV-00013 | D14: 46001 | E14: 46031 | F14: 12264.85 | G14: =SUMIF(Customer_Payments!B:B,C14,Customer_Payments!E:E) -> 12264.85 | H14: =MAX(F14-G14,0) -> 0 | I14: =$L$2-E14 -> 60 | J14: =IF(I14<=0,"Current", IF(I14<=30,"1-30", IF(I14<=60,"31-60", IF(I14<=90,"61-90","90+")))) -> 31-60
A15: CUST-052 | B15: =VLOOKUP(A15,Customers!A:B,2,FALSE) -> RetailAxis | C15: INV-00014 | D15: 46098 | E15: 46128 | F15: 11751.24 | G15: =SUMIF(Customer_Payments!B:B,C15,Customer_Payments!E:E) -> 11751.24 | H15: =MAX(F15-G15,0) -> 0 | I15: =$L$2-E15 -> -37 | J15: =IF(I15<=0,"Current", IF(I15<=30,"1-30", IF(I15<=60,"31-60", IF(I15<=90,"61-90","90+")))) -> Current
... A19: CUST-028 | B19: =VLOOKUP(A19,Customers!A:B,2,FALSE) -> OptiCommerce | C19: INV-00018 | D19: 45979 | E19: 46009 | F19: 2119.55 | G19: =SUMIF(Customer_Payments!B:B,C19,Customer_Payments!E:E) -> 2119.55 | H19: =MAX(F19-G19,0) -> 0 | I19: =$L$2-E19 -> 82 | J19: =IF(I19<=0,"Current", IF(I19<=30,"1-30", IF(I19<=60,"31-60", IF(I19<=90,"61-90","90+")))) -> 61-90
A20: CUST-068 | B20: =VLOOKUP(A20,Customers!A:B,2,FALSE) -> RetailPrime | C20: INV-00019 | D20: 45988 | E20: 46018 | F20: 1788.62 | G20: 700 | H20: =MAX(F20-G20,0) -> 1088.62 | I20: =$L$2-E20 -> 73 | J20: =IF(I20<=0,"Current", IF(I20<=30,"1-30", IF(I20<=60,"31-60", IF(I20<=90,"61-90","90+")))) -> 61-90
A21: CUST-047 | B21: =VLOOKUP(A21,Customers!A:B,2,FALSE) -> PrimeCart | C21: INV-00020 | D21: 46054 | E21: 46084 | F21: 3196.2 | G21: =SUMIF(Customer_Payments!B:B,C21,Customer_Payments!E:E) -> 3196.2 | H21: =MAX(F21-G21,0) -> 0 | I21: =$L$2-E21 -> 7 | J21: =IF(I21<=0,"Current", IF(I21<=30,"1-30", IF(I21<=60,"31-60", IF(I21<=90,"61-90","90+")))) -> 1-30
A22: CUST-006 | B22: =VLOOKUP(A22,Customers!A:B,2,FALSE) -> ShopOrbit | C22: INV-00021 | D22: 46080 | E22: 46110 | F22: 4604.54 | G22: =SUMIF(Customer_Payments!B:B,C22,Customer_Payments!E:E) -> 4604.54 | H22: =MAX(F22-G22,0) -> 0 | I22: =$L$2-E22 -> -19 | J22: =IF(I22<=0,"Current", IF(I22<=30,"1-30", IF(I22<=60,"31-60", IF(I22<=90,"61-90","90+")))) -> Current
A23: CUST-097 | B23: =VLOOKUP(A23,Customers!A:B,2,FALSE) -> RetailVisionPro | C23: INV-00022 | D23: 46082 | E23: 46112 | F23: 3064.03 | G23: =SUMIF(Customer_Payments!B:B,C23,Customer_Payments!E:E) -> 3064.03 | H23: =MAX(F23-G23,0) -> 0 | I23: =$L$2-E23 -> -21 | J23: =IF(I23<=0,"Current", IF(I23<=30,"1-30", IF(I23<=60,"31-60", IF(I23<=90,"61-90","90+")))) -> Current
A24: CUST-062 | B24: =VLOOKUP(A24,Customers!A:B,2,FALSE) -> RetailVision | C24: INV-00023 | D24: 46026 | E24: 46056 | F24: 10092.42 | G24: =SUMIF(Customer_Payments!B:B,C24,Customer_Payments!E:E) -> 10092.42 | H24: =MAX(F24-G24,0) -> 0 | I24: =$L$2-E24 -> 35 | J24: =IF(I24<=0,"Current", IF(I24<=30,"1-30", IF(I24<=60,"31-60", IF(I24<=90,"61-90","90+")))) -> 31-60
A25: CUST-062 | B25: =VLOOKUP(A25,Customers!A:B,2,FALSE) -> RetailVision | C25: INV-00024 | D25: 46022 | E25: 46052 | F25: 11235.39 | G25: =SUMIF(Customer_Payments!B:B,C25,Customer_Payments!E:E) -> 0 | H25: =MAX(F25-G25,0) -> 11235.39 | I25: =$L$2-E25 -> 39 | J25: =IF(I25<=0,"Current", IF(I25<=30,"1-30", IF(I25<=60,"31-60", IF(I25<=90,"61-90","90+")))) -> 31-60
A26: CUST-081 | B26: =VLOOKUP(A26,Customers!A:B,2,FALSE) -> RetailStreamX | C26: INV-00025 | D26: 45968 | E26: 45998 | F26: 3386.54 | G26: =SUMIF(Customer_Payments!B:B,C26,Customer_Payments!E:E) -> 3386.54 | H26: =MAX(F26-G26,0) -> 0 | I26: =$L$2-E26 -> 93 | J26: =IF(I26<=0,"Current", IF(I26<=30,"1-30", IF(I26<=60,"31-60", IF(I26<=90,"61-90","90+")))) -> 90+
A27: CUST-011 | B27: =VLOOKUP(A27,Customers!A:B,2,FALSE) -> AlphaCommerce | C27: INV-00026 | D27: 45997 | E27: 46027 | F27: 1478.6 | G27: =SUMIF(Customer_Payments!B:B,C27,Customer_Payments!E:E) -> 0 | H27: =MAX(F27-G27,0) -> 1478.6 | I27: =$L$2-E27 -> 64 | J27: =IF(I27<=0,"Current", IF(I27<=30,"1-30", IF(I27<=60,"31-60", IF(I27<=90,"61-90","90+")))) -> 61-90
A28: CUST-102 | B28: =VLOOKUP(A28,Customers!A:B,2,FALSE) -> RetailNextPro | C28: INV-00027 | D28: 46022 | E28: 46052 | F28: 4236.9 | G28: =SUMIF(Customer_Payments!B:B,C28,Customer_Payments!E:E) -> 4236.9 | H28: =MAX(F28-G28,0) -> 0 | I28: =$L$2-E28 -> 39 | J28: =IF(I28<=0,"Current", IF(I28<=30,"1-30", IF(I28<=60,"31-60", IF(I28<=90,"61-90","90+")))) -> 31-60
A29: CUST-057 | B29: =VLOOKUP(A29,Customers!A:B,2,FALSE) -> RetailCore | C29: INV-00028 | D29: 46045 | E29: 46075 | F29: 3115.96 | G29: =SUMIF(Customer_Payments!B:B,C29,Customer_Payments!E:E) -> 3115.96 | H29: =MAX(F29-G29,0) -> 0 | I29: =$L$2-E29 -> 16 | J29: =IF(I29<=0,"Current", IF(I29<=30,"1-30", IF(I29<=60,"31-60", IF(I29<=90,"61-90","90+")))) -> 1-30
A30: CUST-008 | B30: =VLOOKUP(A30,Customers!A:B,2,FALSE) -> MarketPulse | C30: INV-00029 | D30: 46068 | E30: 46098 | F30: 2860.17 | G30: =SUMIF(Customer_Payments!B:B,C30,Customer_Payments!E:E) -> 2860.17 | H30: =MAX(F30-G30,0) -> 0 | I30: =$L$2-E30 -> -7 | J30: =IF(I30<=0,"Current", IF(I30<=30,"1-30", IF(I30<=60,"31-60", IF(I30<=90,"61-90","90+")))) -> Current
A31: CUST-034 | B31: =VLOOKUP(A31,Customers!A:B,2,FALSE) -> GlobalCart | C31: INV-00030 | D31: 46066 | E31: 46096 | F31: 4144.15 | G31: =SUMIF(Customer_Payments!B:B,C31,Customer_Payments!E:E) -> 4144.15 | H31: =MAX(F31-G31,0) -> 0 | I31: =$L$2-E31 -> -5 | J31: =IF(I31<=0,"Current", IF(I31<=30,"1-30", IF(I31<=60,"31-60", IF(I31<=90,"61-90","90+")))) -> Current
A32: CUST-021 | B32: =VLOOKUP(A32,Customers!A:B,2,FALSE) -> Skyline Commerce | C32: INV-00031 | D32: 45982 | E32: 46012 | F32: 1498.45 | G32: =SUMIF(Customer_Payments!B:B,C32,Customer_Payments!E:E) -> 1498.45 | H32: =MAX(F32-G32,0) -> 0 | I32: =$L$2-E32 -> 79 | J32: =IF(I32<=0,"Current", IF(I32<=30,"1-30", IF(I32<=60,"31-60", IF(I32<=90,"61-90","90+")))) -> 61-90
... A41: CUST-074 | B41: =VLOOKUP(A41,Customers!A:B,2,FALSE) -> RetailEdgeX | C41: INV-00040 | D41: 46100 | E41: 46130 | F41: 2025.86 | G41: =SUMIF(Customer_Payments!B:B,C41,Customer_Payments!E:E) -> 0 | H41: =MAX(F41-G41,0) -> 2025.86 | I41: =$L$2-E41 -> -39 | J41: =IF(I41<=0,"Current", IF(I41<=30,"1-30", IF(I41<=60,"31-60", IF(I41<=90,"61-90","90+")))) -> Current
A42: CUST-074 | B42: =VLOOKUP(A42,Customers!A:B,2,FALSE) -> RetailEdgeX | C42: INV-00041 | D42: 46022 | E42: 46052 | F42: 4131.1 | G42: 2500 | H42: =MAX(F42-G42,0) -> 1631.1 | I42: =$L$2-E42 -> 39 | J42: =IF(I42<=0,"Current", IF(I42<=30,"1-30", IF(I42<=60,"31-60", IF(I42<=90,"61-90","90+")))) -> 31-60
A43: CUST-057 | B43: =VLOOKUP(A43,Customers!A:B,2,FALSE) -> RetailCore | C43: INV-00042 | D43: 46101 | E43: 46131 | F43: 3315.73 | G43: =SUMIF(Customer_Payments!B:B,C43,Customer_Payments!E:E) -> 3315.73 | H43: =MAX(F43-G43,0) -> 0 | I43: =$L$2-E43 -> -40 | J43: =IF(I43<=0,"Current", IF(I43<=30,"1-30", IF(I43<=60,"31-60", IF(I43<=90,"61-90","90+")))) -> Current
A44: CUST-063 | B44: =VLOOKUP(A44,Customers!A:B,2,FALSE) -> RetailNext | C44: INV-00043 | D44: 45982 | E44: 46012 | F44: 2181.49 | G44: =SUMIF(Customer_Payments!B:B,C44,Customer_Payments!E:E) -> 2181.49 | H44: =MAX(F44-G44,0) -> 0 | I44: =$L$2-E44 -> 79 | J44: =IF(I44<=0,"Current", IF(I44<=30,"1-30", IF(I44<=60,"31-60", IF(I44<=90,"61-90","90+")))) -> 61-90
A45: CUST-014 | B45: =VLOOKUP(A45,Customers!A:B,2,FALSE) -> GrowthSphere | C45: INV-00044 | D45: 46041 | E45: 46071 | F45: 2964.01 | G45: =SUMIF(Customer_Payments!B:B,C45,Customer_Payments!E:E) -> 2964.01 | H45: =MAX(F45-G45,0) -> 0 | I45: =$L$2-E45 -> 20 | J45: =IF(I45<=0,"Current", IF(I45<=30,"1-30", IF(I45<=60,"31-60", IF(I45<=90,"61-90","90+")))) -> 1-30
A46: CUST-052 | B46: =VLOOKUP(A46,Customers!A:B,2,FALSE) -> RetailAxis | C46: INV-00045 | D46: 46112 | E46: 46142 | F46: 4659.61 | G46: =SUMIF(Customer_Payments!B:B,C46,Customer_Payments!E:E) -> 4659.61 | H46: =MAX(F46-G46,0) -> 0 | I46: =$L$2-E46 -> -51 | J46: =IF(I46<=0,"Current", IF(I46<=30,"1-30", IF(I46<=60,"31-60", IF(I46<=90,"61-90","90+")))) -> Current
A47: CUST-015 | B47: =VLOOKUP(A47,Customers!A:B,2,FALSE) -> InsightLoop | C47: INV-00046 | D47: 45970 | E47: 46000 | F47: 2851.38 | G47: =SUMIF(Customer_Payments!B:B,C47,Customer_Payments!E:E) -> 2851.38 | H47: =MAX(F47-G47,0) -> 0 | I47: =$L$2-E47 -> 91 | J47: =IF(I47<=0,"Current", IF(I47<=30,"1-30", IF(I47<=60,"31-60", IF(I47<=90,"61-90","90+")))) -> 90+
A48: CUST-070 | B48: =VLOOKUP(A48,Customers!A:B,2,FALSE) -> RetailSphere | C48: INV-00047 | D48: 46071 | E48: 46101 | F48: 13751.57 | G48: =SUMIF(Customer_Payments!B:B,C48,Customer_Payments!E:E) -> 13751.57 | H48: =MAX(F48-G48,0) -> 0 | I48: =$L$2-E48 -> -10 | J48: =IF(I48<=0,"Current", IF(I48<=30,"1-30", IF(I48<=60,"31-60", IF(I48<=90,"61-90","90+")))) -> Current
A49: CUST-097 | B49: =VLOOKUP(A49,Customers!A:B,2,FALSE) -> RetailVisionPro | C49: INV-00048 | D49: 45985 | E49: 46015 | F49: 11583.59 | G49: =SUMIF(Customer_Payments!B:B,C49,Customer_Payments!E:E) -> 11583.59 | H49: =MAX(F49-G49,0) -> 0 | I49: =$L$2-E49 -> 76 | J49: =IF(I49<=0,"Current", IF(I49<=30,"1-30", IF(I49<=60,"31-60", IF(I49<=90,"61-90","90+")))) -> 61-90
A50: CUST-071 | B50: =VLOOKUP(A50,Customers!A:B,2,FALSE) -> RetailBridge | C50: INV-00049 | D50: 45971 | E50: 46001 | F50: 12601.96 | G50: =SUMIF(Customer_Payments!B:B,C50,Customer_Payments!E:E) -> 12601.96 | H50: =MAX(F50-G50,0) -> 0 | I50: =$L$2-E50 -> 90 | J50: =IF(I50<=0,"Current", IF(I50<=30,"1-30", IF(I50<=60,"31-60", IF(I50<=90,"61-90","90+")))) -> 61-90
A51: CUST-004 | B51: =VLOOKUP(A51,Customers!A:B,2,FALSE) -> LaunchLabs | C51: INV-00050 | D51: 46071 | E51: 46101 | F51: 5855.35 | G51: =SUMIF(Customer_Payments!B:B,C51,Customer_Payments!E:E) -> 5855.35 | H51: =MAX(F51-G51,0) -> 0 | I51: =$L$2-E51 -> -10 | J51: =IF(I51<=0,"Current", IF(I51<=30,"1-30", IF(I51<=60,"31-60", IF(I51<=90,"61-90","90+")))) -> Current
...

Sheet AR_Aging_Summary
A1: ACCOUNTS RECEIVABLE AGING SUMMARY
A2: Report Date: March 10, 2026
A4: Aging Bucket | B4: Outstanding Balance | C4: % of Total AR
A5: Current | B5: =SUMIF(AR_Aging!J:J,"Current",AR_Aging!H:H) -> 1042557.4 | C5: =B5/$B$10 -> 0.32534504
A6: 1-30 Days | B6: =SUMIF(AR_Aging!J:J,"1-30",AR_Aging!H:H) -> 699592.25 | C6: =B6/$B$10 -> 0.21831783
A7: 31-60 Days | B7: =SUMIF(AR_Aging!J:J,"31-60",AR_Aging!H:H) -> 589117.49 | C7: =B7/$B$10 -> 0.18384259
A8: 61-90 Days | B8: =SUMIF(AR_Aging!J:J,"61-90",AR_Aging!H:H) -> 702523.27 | C8: =B8/$B$10 -> 0.21923249
A9: 90+ Days | B9: =SUMIF(AR_Aging!J:J,"90+",AR_Aging!H:H) -> 170676.46 | C9: =B9/$B$10 -> 0.053262044
A10: Total | B10: =SUM(B5:B9) -> 3204466.9 | C10: =SUM(C5:C9) -> 1
B20: Aging Bucket | C20: % of Total AR
B21: Current | C21: 0.32534504
B22: 1-30 Days | C22: 0.21831783
B23: 31-60 Days | C23: 0.18384259
B24: 61-90 Days | C24: 0.21923249
B25: 90+ Days | C25: 0.053262044
B26: Total | C26: 1

Sheet Vendor_Bills
A1: BillID | B1: VendorID | C1: BillDate | D1: DueDate | E1: BillAmount | F1: Status
A2: BILL-00001 | B2: VEN-016 | C2: 46065 | D2: 46095 | E2: 5918.09 | F2: Paid
A3: BILL-00002 | B3: VEN-028 | C3: 46035 | D3: 46065 | E3: 6605.3 | F3: Paid
A4: BILL-00003 | B4: VEN-012 | C4: 45964 | D4: 45994 | E4: 5834.93 | F4: Paid
A5: BILL-00004 | B5: VEN-031 | C5: 46004 | D5: 46034 | E5: 4168.49 | F5: Paid
A6: BILL-00005 | B6: VEN-028 | C6: 46063 | D6: 46093 | E6: 1940.52 | F6: Paid
A7: BILL-00006 | B7: VEN-008 | C7: 46059 | D7: 46089 | E7: 3560.06 | F7: Paid
A8: BILL-00007 | B8: VEN-014 | C8: 45986 | D8: 46016 | E8: 6544.81 | F8: Open
A9: BILL-00008 | B9: VEN-004 | C9: 45996 | D9: 46026 | E9: 1429.47 | F9: Paid
A10: BILL-00009 | B10: VEN-028 | C10: 45979 | D10: 46009 | E10: 5050.47 | F10: Paid
A11: BILL-00010 | B11: VEN-032 | C11: 46002 | D11: 46032 | E11: 1343.26 | F11: Paid
A12: BILL-00011 | B12: VEN-011 | C12: 45976 | D12: 46006 | E12: 4473.44 | F12: Paid
A13: BILL-00012 | B13: VEN-015 | C13: 46027 | D13: 46057 | E13: 2101.38 | F13: Paid
... A1401: BILL-01400 | B1401: VEN-026 | C1401: 45968 | D1401: 45998 | E1401: 5542.46 | F1401: Paid

Sheet Vendor_Payments
A1: PaymentID | B1: VendorID | C1: BillID | D1: PaymentDate | E1: PaymentAmount | F1: Method
A2: VPAY-00001 | B2: VEN-016 | C2: BILL-00001 | D2: 46082 | E2: 5918.09 | F2: ACH
A3: VPAY-00002 | B3: VEN-028 | C3: BILL-00002 | D3: 46036 | E3: 6605.3 | F3: Bank Transfer
A4: VPAY-00003 | B4: VEN-012 | C4: BILL-00003 | D4: 45967 | E4: 5834.93 | F4: Bank Transfer
A5: VPAY-00004 | B5: VEN-031 | C5: BILL-00004 | D5: 46015 | E5: 4168.49 | F5: ACH
A6: VPAY-00005 | B6: VEN-028 | C6: BILL-00005 | D6: 46059 | E6: 1940.52 | F6: Bank Transfer
A7: VPAY-00006 | B7: VEN-008 | C7: BILL-00006 | D7: 46066 | E7: 3560.06 | F7: Bank Transfer
A8: VPAY-00007 | B8: VEN-004 | C8: BILL-00008 | D8: 46009 | E8: 1429.47 | F8: Credit Card
A9: VPAY-00008 | B9: VEN-028 | C9: BILL-00009 | D9: 45999 | E9: 5050.47 | F9: ACH
A10: VPAY-00009 | B10: VEN-032 | C10: BILL-00010 | D10: 46012 | E10: 1343.26 | F10: Bank Transfer
A11: VPAY-00010 | B11: VEN-011 | C11: BILL-00011 | D11: 45995 | E11: 4473.44 | F11: Credit Card
A12: VPAY-00011 | B12: VEN-015 | C12: BILL-00012 | D12: 46029 | E12: 2101.38 | F12: Bank Transfer
A13: VPAY-00012 | B13: VEN-037 | C13: BILL-00013 | D13: 46061 | E13: 2393.11 | F13: Credit Card
... A989: VPAY-00988 | B989: VEN-026 | C989: BILL-01400 | D989: 45982 | E989: 5542.46 | F989: ACH

Sheet AP_Aging
A1: BillID | B1: VendorID | C1: VendorName | D1: BillDate | E1: DueDate | F1: BillAmount | G1: AmountPaid | H1: OutstandingBalance | I1: DaysOutstanding | J1: AgingBucket | L1: 46091
A2: =Table3[[#This Row],[BillID]] -> BILL-00001 | B2: =Table3[[#This Row],[VendorID]] -> VEN-016 | C2: =VLOOKUP(B2,Vendors!A:B,2,FALSE) -> Stripe | D2: =Table3[[#This Row],[BillDate]] -> 46065 | E2: =Table3[[#This Row],[DueDate]] -> 46095 | F2: =Table3[[#This Row],[BillAmount]] -> 5918.09 | G2: =SUMIF(Vendor_Payments!C:C,A2,Vendor_Payments!E:E) -> 5918.09 | H2: =F2-G2 -> 0 | I2: =$L$1-E2 -> -4 | J2: =IF(I2<=0,"Current",IF(I2<=30,"1-30",IF(I2<=60,"31-60",IF(I2<=90,"61-90","90+")))) -> Current
A3: =Table3[[#This Row],[BillID]] -> BILL-00002 | B3: =Table3[[#This Row],[VendorID]] -> VEN-028 | C3: =VLOOKUP(B3,Vendors!A:B,2,FALSE) -> MarketEdge Consulting | D3: =Table3[[#This Row],[BillDate]] -> 46035 | E3: =Table3[[#This Row],[DueDate]] -> 46065 | F3: =Table3[[#This Row],[BillAmount]] -> 6605.3 | G3: =SUMIF(Vendor_Payments!C:C,A3,Vendor_Payments!E:E) -> 6605.3 | H3: =F3-G3 -> 0 | I3: =$L$1-E3 -> 26 | J3: =IF(I3<=0,"Current",IF(I3<=30,"1-30",IF(I3<=60,"31-60",IF(I3<=90,"61-90","90+")))) -> 1-30
A4: =Table3[[#This Row],[BillID]] -> BILL-00003 | B4: =Table3[[#This Row],[VendorID]] -> VEN-012 | C4: =VLOOKUP(B4,Vendors!A:B,2,FALSE) -> Google Cloud | D4: =Table3[[#This Row],[BillDate]] -> 45964 | E4: =Table3[[#This Row],[DueDate]] -> 45994 | F4: =Table3[[#This Row],[BillAmount]] -> 5834.93 | G4: =SUMIF(Vendor_Payments!C:C,A4,Vendor_Payments!E:E) -> 5834.93 | H4: =F4-G4 -> 0 | I4: =$L$1-E4 -> 97 | J4: =IF(I4<=0,"Current",IF(I4<=30,"1-30",IF(I4<=60,"31-60",IF(I4<=90,"61-90","90+")))) -> 90+
A5: =Table3[[#This Row],[BillID]] -> BILL-00004 | B5: =Table3[[#This Row],[VendorID]] -> VEN-031 | C5: =VLOOKUP(B5,Vendors!A:B,2,FALSE) -> DataInsight Analytics | D5: =Table3[[#This Row],[BillDate]] -> 46004 | E5: =Table3[[#This Row],[DueDate]] -> 46034 | F5: =Table3[[#This Row],[BillAmount]] -> 4168.49 | G5: =SUMIF(Vendor_Payments!C:C,A5,Vendor_Payments!E:E) -> 4168.49 | H5: =F5-G5 -> 0 | I5: =$L$1-E5 -> 57 | J5: =IF(I5<=0,"Current",IF(I5<=30,"1-30",IF(I5<=60,"31-60",IF(I5<=90,"61-90","90+")))) -> 31-60
A6: =Table3[[#This Row],[BillID]] -> BILL-00005 | B6: =Table3[[#This Row],[VendorID]] -> VEN-028 | C6: =VLOOKUP(B6,Vendors!A:B,2,FALSE) -> MarketEdge Consulting | D6: =Table3[[#This Row],[BillDate]] -> 46063 | E6: =Table3[[#This Row],[DueDate]] -> 46093 | F6: =Table3[[#This Row],[BillAmount]] -> 1940.52 | G6: =SUMIF(Vendor_Payments!C:C,A6,Vendor_Payments!E:E) -> 1940.52 | H6: =F6-G6 -> 0 | I6: =$L$1-E6 -> -2 | J6: =IF(I6<=0,"Current",IF(I6<=30,"1-30",IF(I6<=60,"31-60",IF(I6<=90,"61-90","90+")))) -> Current
A7: =Table3[[#This Row],[BillID]] -> BILL-00006 | B7: =Table3[[#This Row],[VendorID]] -> VEN-008 | C7: =VLOOKUP(B7,Vendors!A:B,2,FALSE) -> Ahrefs | D7: =Table3[[#This Row],[BillDate]] -> 46059 | E7: =Table3[[#This Row],[DueDate]] -> 46089 | F7: =Table3[[#This Row],[BillAmount]] -> 3560.06 | G7: =SUMIF(Vendor_Payments!C:C,A7,Vendor_Payments!E:E) -> 3560.06 | H7: =F7-G7 -> 0 | I7: =$L$1-E7 -> 2 | J7: =IF(I7<=0,"Current",IF(I7<=30,"1-30",IF(I7<=60,"31-60",IF(I7<=90,"61-90","90+")))) -> 1-30
A8: =Table3[[#This Row],[BillID]] -> BILL-00007 | B8: =Table3[[#This Row],[VendorID]] -> VEN-014 | C8: =VLOOKUP(B8,Vendors!A:B,2,FALSE) -> Figma | D8: =Table3[[#This Row],[BillDate]] -> 45986 | E8: =Table3[[#This Row],[DueDate]] -> 46016 | F8: =Table3[[#This Row],[BillAmount]] -> 6544.81 | G8: =SUMIF(Vendor_Payments!C:C,A8,Vendor_Payments!E:E) -> 0 | H8: =F8-G8 -> 6544.81 | I8: =$L$1-E8 -> 75 | J8: =IF(I8<=0,"Current",IF(I8<=30,"1-30",IF(I8<=60,"31-60",IF(I8<=90,"61-90","90+")))) -> 61-90
A9: =Table3[[#This Row],[BillID]] -> BILL-00008 | B9: =Table3[[#This Row],[VendorID]] -> VEN-004 | C9: =VLOOKUP(B9,Vendors!A:B,2,FALSE) -> LinkedIn Ads | D9: =Table3[[#This Row],[BillDate]] -> 45996 | E9: =Table3[[#This Row],[DueDate]] -> 46026 | F9: =Table3[[#This Row],[BillAmount]] -> 1429.47 | G9: =SUMIF(Vendor_Payments!C:C,A9,Vendor_Payments!E:E) -> 1429.47 | H9: =F9-G9 -> 0 | I9: =$L$1-E9 -> 65 | J9: =IF(I9<=0,"Current",IF(I9<=30,"1-30",IF(I9<=60,"31-60",IF(I9<=90,"61-90","90+")))) -> 61-90
A10: =Table3[[#This Row],[BillID]] -> BILL-00009 | B10: =Table3[[#This Row],[VendorID]] -> VEN-028 | C10: =VLOOKUP(B10,Vendors!A:B,2,FALSE) -> MarketEdge Consulting | D10: =Table3[[#This Row],[BillDate]] -> 45979 | E10: =Table3[[#This Row],[DueDate]] -> 46009 | F10: =Table3[[#This Row],[BillAmount]] -> 5050.47 | G10: =SUMIF(Vendor_Payments!C:C,A10,Vendor_Payments!E:E) -> 5050.47 | H10: =F10-G10 -> 0 | I10: =$L$1-E10 -> 82 | J10: =IF(I10<=0,"Current",IF(I10<=30,"1-30",IF(I10<=60,"31-60",IF(I10<=90,"61-90","90+")))) -> 61-90
A11: =Table3[[#This Row],[BillID]] -> BILL-00010 | B11: =Table3[[#This Row],[VendorID]] -> VEN-032 | C11: =VLOOKUP(B11,Vendors!A:B,2,FALSE) -> Marketing Automation Labs | D11: =Table3[[#This Row],[BillDate]] -> 46002 | E11: =Table3[[#This Row],[DueDate]] -> 46032 | F11: =Table3[[#This Row],[BillAmount]] -> 1343.26 | G11: =SUMIF(Vendor_Payments!C:C,A11,Vendor_Payments!E:E) -> 1343.26 | H11: =F11-G11 -> 0 | I11: =$L$1-E11 -> 59 | J11: =IF(I11<=0,"Current",IF(I11<=30,"1-30",IF(I11<=60,"31-60",IF(I11<=90,"61-90","90+")))) -> 31-60
A12: =Table3[[#This Row],[BillID]] -> BILL-00011 | B12: =Table3[[#This Row],[VendorID]] -> VEN-011 | C12: =VLOOKUP(B12,Vendors!A:B,2,FALSE) -> AWS | D12: =Table3[[#This Row],[BillDate]] -> 45976 | E12: =Table3[[#This Row],[DueDate]] -> 46006 | F12: =Table3[[#This Row],[BillAmount]] -> 4473.44 | G12: =SUMIF(Vendor_Payments!C:C,A12,Vendor_Payments!E:E) -> 4473.44 | H12: =F12-G12 -> 0 | I12: =$L$1-E12 -> 85 | J12: =IF(I12<=0,"Current",IF(I12<=30,"1-30",IF(I12<=60,"31-60",IF(I12<=90,"61-90","90+")))) -> 61-90
A13: =Table3[[#This Row],[BillID]] -> BILL-00012 | B13: =Table3[[#This Row],[VendorID]] -> VEN-015 | C13: =VLOOKUP(B13,Vendors!A:B,2,FALSE) -> Zapier | D13: =Table3[[#This Row],[BillDate]] -> 46027 | E13: =Table3[[#This Row],[DueDate]] -> 46057 | F13: =Table3[[#This Row],[BillAmount]] -> 2101.38 | G13: =SUMIF(Vendor_Payments!C:C,A13,Vendor_Payments!E:E) -> 2101.38 | H13: =F13-G13 -> 0 | I13: =$L$1-E13 -> 34 | J13: =IF(I13<=0,"Current",IF(I13<=30,"1-30",IF(I13<=60,"31-60",IF(I13<=90,"61-90","90+")))) -> 31-60
... A1401: =Table3[[#This Row],[BillID]] -> BILL-01400 | B1401: =Table3[[#This Row],[VendorID]] -> VEN-026 | C1401: =VLOOKUP(B1401,Vendors!A:B,2,FALSE) -> PixelForge Studio | D1401: =Table3[[#This Row],[BillDate]] -> 45968 | E1401: =Table3[[#This Row],[DueDate]] -> 45998 | F1401: =Table3[[#This Row],[BillAmount]] -> 5542.46 | G1401: =SUMIF(Vendor_Payments!C:C,A1401,Vendor_Payments!E:E) -> 5542.46 | H1401: =F1401-G1401 -> 0 | I1401: =$L$1-E1401 -> 93 | J1401: =IF(I1401<=0,"Current",IF(I1401<=30,"1-30",IF(I1401<=60,"31-60",IF(I1401<=90,"61-90","90+")))) -> 90+

Sheet AP_Aging_Summary
A1: NovaTech Commerce Ltd
A2: Accounts Payable Aging Summary
A3: As of March 10, 2026
A6: Aging Brucket | B6: Outstanding Balance | C6: % of Total AP | G6: Current | H6: 0.23398967
A7: Current | B7: =SUMIF(AP_Aging!J:J,"Current",AP_Aging!H:H) -> 369681.95 | C7: =B7/$B$12 -> 0.23398967 | G7: 1-30 Days | H7: 0.23022568
A8: 1-30 Days | B8: =SUMIF(AP_Aging!J:J,"1-30",AP_Aging!H:H) -> 363735.19 | C8: =B8/$B$12 -> 0.23022568 | G8: 31-60 Days | H8: 0.23326672
A9: 31-60 Days | B9: =SUMIF(AP_Aging!J:J,"31-60",AP_Aging!H:H) -> 368539.75 | C9: =B9/$B$12 -> 0.23326672 | G9: 61-90 Days | H9: 0.21919067
A10: 61-90 Days | B10: =SUMIF(AP_Aging!J:J,"61-90",AP_Aging!H:H) -> 346300.91 | C10: =B10/$B$12 -> 0.21919067 | G10: 90+ Days | H10: 0.083327264
A11: 90+ Days | B11: =SUMIF(AP_Aging!J:J,"90+",AP_Aging!H:H) -> 131649.34 | C11: =B11/$B$12 -> 0.083327264
A12: Total AP | B12: =SUM(B7:B11) -> 1579907.1 | C12: =SUM(C7:C11) -> 1
B18: 0=

Sheet Bank_Transactions
A1: TransactionDate | B1: Description | C1: Amount | D1: Type | E1: ReferenceID
A2: 46056 | B2: Payroll | C2: -94788.88 | D2: Withdrawal | E2: PAYROLL
A3: 46077 | B3: Vendor Payment | C3: -4415.61 | D3: Withdrawal | E3: VPAY-00622
A4: 46039 | B4: Customer Payment | C4: 2106.55 | D4: Deposit | E4: PAY-00306
A5: 46043 | B5: Customer Payment | C5: 13480.07 | D5: Deposit | E5: PAY-01413
A6: 46025 | B6: Customer Payment | C6: 3572.3 | D6: Deposit | E6: PAY-00292
A7: 46015 | B7: Customer Payment | C7: 9844.43 | D7: Deposit | E7: PAY-01114
A8: 46017 | B8: Vendor Payment | C8: -6110.16 | D8: Withdrawal | E8: VPAY-00220
A9: 46080 | B9: Customer Payment | C9: 2818.9 | D9: Deposit | E9: PAY-01473
A10: 46022 | B10: Customer Payment | C10: 3428.41 | D10: Deposit | E10: PAY-01208
A11: 45966 | B11: Vendor Payment | C11: -2049.86 | D11: Withdrawal | E11: VPAY-00531
A12: 46070 | B12: Customer Payment | C12: 13804.52 | D12: Deposit | E12: PAY-02010
A13: 46081 | B13: Vendor Payment | C13: -4912.69 | D13: Withdrawal | E13: VPAY-00712
... A3245: 46064 | B3245: Vendor Payment | C3245: -5139.03 | D3245: Withdrawal | E3245: VPAY-00492

Sheet Finance_KPIs
A1: NovaTech Commerce Ltd
A2: Financial Performance Dashboard
A3: Period: Nov 2025 - Mar 2026
A6: Revenue & Profitability
A7: Total Revenue | B7: =SUM(Sales_Invoices!F:F) -> 13108097
A8: Cost of Goods Sold | B8: =SUM(Vendor_Bills!E:E) -> 5427727.9
A9: Gross Profit | B9: =B7-B8 -> 7680369.3
A10: Gross Margin | B10: =B9/B7 -> 0.58592557
A12: Working Capital
A13: Total Accounts Receivable | B13: =SUM(AR_Aging!H:H) -> 3204466.9
A14: Total Accounts Payable | B14: =SUM(AP_Aging!H:H) -> 1579907.1
A15: Cash Balance | B15: =SUM(Bank_Transactions!C:C) -> 4320290.8
A17: Efficiency Metrics
A18: Days Sales Outstanding (DSO) | B18: =B13/(B7/365) -> 89.229611
A19: Days Payable Outstanding (DPO) | B19: =B14/(B8/365) -> 106.24448
A20: Cash Conversion Cycle (CCC) | B20: =B18-B19 -> -17.014865
